Workbook

Sheet Dashboard Final Score
A1: Deadline: Thu 11 June, 13:00. Check all scores 10 minutes before; Excel will be locked after.
A4: Group Stage | I4: Ryan | J4: Jonathan | K4: Raadin | L4: Tania | M4: Jeff | N4: Luw | O4: Ashraf | P4: Naomie | Q4: Charlene | R4: Valerie | S4: Keshav | T4: Mohnish | U4: Nicolas | V4: Julien | W4: Andrew | X4: Jenna | Y4: Janish | Z4: Sandrassen | AA4: Jessy | AB4: Prashant | AC4: Geetika | AD4: Joakim | AE4: Ouvarshi | AF4: Stephane | AG4: Irfaan | AH4: Ervin | AI4: Noemi | AJ4: Isfaaq | AK4: Ahmad | AL4: Parikshit | AM4: Jaya | AN4: Elodie | AO4: Ravindra | AP4: Jessen | AQ4: Annavi | AR4: LUDOVIC.L | AS4: Nathalie | AT4: Akshay | AU4: Bavish | AV4: Itish | AW4: Oumar | AX4: Kesh | AY4: ADHISH | AZ4: Vishnee | BA4: Sebastien | BB4: Soneea | BC4: Geraldine | BD4: Chaya | BE4: Reshmi
A6: 1 | B6: Thu | C6: Jun 11, 2026 | D6: 0.79166667 | E6: Mexico | F6: 2 | G6: 0 | H6: South Africa | I6: =IF(AND(RYAN!F6=F6,RYAN!G6=G6),"Win","Lose") -> Lose | J6: =IF(AND(JONATHAN!F6=F6,JONATHAN!G6=G6),"Win","Lose") -> Win | K6: =IF(AND(RAADIN!F6=F6,RAADIN!G6=G6),"Win","Lose") -> Lose | L6: =IF(AND(TANIA!F6=F6,TANIA!G6=G6),"Win","Lose") -> Lose | M6: =IF(AND(JEFF!F6=F6,JEFF!G6=G6),"Win","Lose") -> Lose | N6: =IF(AND(LUW!F6=F6,LUW!G6=G6),"Win","Lose") -> Lose | O6: =IF(AND(ASHRAF!F6=F6,ASHRAF!G6=G6),"Win","Lose") -> Lose | P6: =IF(AND(NAOMI!F6=F6,NAOMI!G6=G6),"Win","Lose") -> Lose | Q6: =IF(AND(CHARLENE!F6=F6,CHARLENE!G6=G6),"Win","Lose") -> Lose | R6: =IF(AND(VALERIE!F6=F6,VALERIE!G6=G6),"Win","Lose") -> Lose | S6: =IF(AND(KESHAV!F6=F6,KESHAV!G6=G6),"Win","Lose") -> Lose | T6: =IF(AND(MOHNISH!F6=F6,MOHNISH!G6=G6),"Win","Lose") -> Lose | U6: =IF(AND(NICOLAS!F6=F6,NICOLAS!G6=G6),"Win","Lose") -> Lose | V6: =IF(AND(JULIEN!F6=F6,JULIEN!G6=G6),"Win","Lose") -> Win | W6: =IF(AND(ANDREW!F6=F6,ANDREW!G6=G6),"Win","Lose") -> Win | X6: =IF(AND(JENNA!F6=F6,JENNA!G6=G6),"Win","Lose") -> Lose | Y6: =IF(AND(JANISH!F6=F6,JANISH!G6=G6),"Win","Lose") -> Win | Z6: =IF(AND(SANDRASEN!F6=F6,SANDRASEN!G6=G6),"Win","Lose") -> Lose | AA6: =IF(AND(JESSY!F6=F6,JESSY!G6=G6),"Win","Lose") -> Lose | AB6: =IF(AND(PRASHANT!F6=F6,PRASHANT!G6=G6),"Win","Lose") -> Win | AC6: =IF(AND(GEETIKA!F6=F6,GEETIKA!G6=G6),"Win","Lose") -> Win | AD6: =IF(AND(JOAKIM!F6=F6,JOAKIM!G6=G6),"Win","Lose") -> Lose | AE6: =IF(AND(OUVARSHI!F6=F6,OUVARSHI!G6=G6),"Win","Lose") -> Lose | AF6: =IF(AND(STEPHAN!F6=F6,STEPHAN!G6=G6),"Win","Lose") -> Lose | AG6: =IF(AND(IRFAAN!F6=F6,IRFAAN!G6=G6),"Win","Lose") -> Win | AH6: =IF(AND(ERVIN!F8=F8,ERVIN!G8=G8),"Win","Lose") -> Lose | AI6: =IF(AND(NOEMIE!F8=F8,NOEMIE!G8=G8),"Win","Lose") -> Lose | AJ6: =IF(AND(ISFAAQ!F6=F6,ISFAAQ!G6=G6),"Win","Lose") -> Win | AK6: =IF(AND(AHMAD!F6=F6,AHMAD!G6=G6),"Win","Lose") -> Lose | AL6: =IF(AND(PARIKSHIT!F6=F6,PARIKSHIT!G6=G6),"Win","Lose") -> Lose | AM6: =IF(AND(JAYA!F6=F6,JAYA!G6=G6),"Win","Lose") -> Win | AN6: =IF(AND(Elodie!F6=F6,Elodie!G6=G6),"Win","Lose") -> Lose | AO6: =IF(AND(RAVINDRA!F6=F6,RAVINDRA!G6=G6),"Win","Lose") -> Win | AP6: =IF(AND(Jessen!F6=F6,Jessen!G6=G6),"Win","Lose") -> Win | AQ6: =IF(AND(Annavi!F6=F6,Annavi!G6=G6),"Win","Lose") -> Lose | AR6: =IF(AND(LUDOVIC!F6=F6,LUDOVIC!G6=G6),"Win","Lose") -> Win | AS6: =IF(AND(Nathalie!F6=F6,Nathalie!G6=G6),"Win","Lose") -> Lose | AT6: =IF(AND(Akshay!F6=F6,Akshay!G6=G6),"Win","Lose") -> Win | AU6: =IF(AND(Bavish!F6=F6,Bavish!G6=G6),"Win","Lose") -> Lose | AV6: =IF(AND(Itish!F6=F6,Itish!G6=G6),"Win","Lose") -> Lose | AW6: =IF(AND(Oumar!F6=F6,Oumar!G6=G6),"Win","Lose") -> Win | AX6: =IF(AND(Kesh!F6=F6,Kesh!G6=G6),"Win","Lose") -> Lose | AY6: =IF(AND(ADHISH!F6=F6,ADHISH!G6=G6),"Win","Lose") -> Win | AZ6: =IF(AND(Vishnee!F6=F6,Vishnee!G6=G6),"Win","Lose") -> Lose | BA6: =IF(AND(Sebastien!F6=F6,Sebastien!G6=G6),"Win","Lose") -> Win | BB6: =IF(AND(Soneea!F6=F6,Soneea!G6=G6),"Win","Lose") -> Win | BC6: =IF(AND(Geraldine!F6=F6,Geraldine!G6=G6),"Win","Lose") -> Win | BD6: =IF(AND(Chaya!F6=F6,Chaya!G6=G6),"Win","Lose") -> Win | BE6: =IF(AND(Reshmi!F6=F6,Reshmi!G6=G6),"Win","Lose") -> Lose
A7: 2 | B7: Fri | C7: Jun 12, 2026 | D7: 0.083333333 | E7: Korea Republic | F7: 2 | G7: 1 | H7: Czech Republic | I7: =IF(AND(RYAN!F7=F7,RYAN!G7=G7),"Win","Lose") -> Lose | J7: =IF(AND(JONATHAN!F7=F7,JONATHAN!G7=G7),"Win","Lose") -> Lose | K7: =IF(AND(RAADIN!F7=F7,RAADIN!G7=G7),"Win","Lose") -> Lose | L7: =IF(AND(TANIA!F7=F7,TANIA!G7=G7),"Win","Lose") -> Lose | M7: =IF(AND(JEFF!F7=F7,JEFF!G7=G7),"Win","Lose") -> Lose | N7: =IF(AND(LUW!F7=F7,LUW!G7=G7),"Win","Lose") -> Win | O7: =IF(AND(ASHRAF!F7=F7,ASHRAF!G7=G7),"Win","Lose") -> Lose | P7: =IF(AND(NAOMI!F7=F7,NAOMI!G7=G7),"Win","Lose") -> Lose | Q7: =IF(AND(CHARLENE!F7=F7,CHARLENE!G7=G7),"Win","Lose") -> Lose | R7: =IF(AND(VALERIE!F7=F7,VALERIE!G7=G7),"Win","Lose") -> Lose | S7: =IF(AND(KESHAV!F7=F7,KESHAV!G7=G7),"Win","Lose") -> Lose | T7: =IF(AND(MOHNISH!F7=F7,MOHNISH!G7=G7),"Win","Lose") -> Lose | U7: =IF(AND(NICOLAS!F7=F7,NICOLAS!G7=G7),"Win","Lose") -> Lose | V7: =IF(AND(JULIEN!F7=F7,JULIEN!G7=G7),"Win","Lose") -> Lose | W7: =IF(AND(ANDREW!F7=F7,ANDREW!G7=G7),"Win","Lose") -> Lose | X7: =IF(AND(JENNA!F7=F7,JENNA!G7=G7),"Win","Lose") -> Lose | Y7: =IF(AND(JANISH!F7=F7,JANISH!G7=G7),"Win","Lose") -> Lose | Z7: =IF(AND(SANDRASEN!F7=F7,SANDRASEN!G7=G7),"Win","Lose") -> Lose | AA7: =IF(AND(JESSY!F7=F7,JESSY!G7=G7),"Win","Lose") -> Lose | AB7: =IF(AND(PRASHANT!F7=F7,PRASHANT!G7=G7),"Win","Lose") -> Lose | AC7: =IF(AND(GEETIKA!F7=F7,GEETIKA!G7=G7),"Win","Lose") -> Lose | AD7: =IF(AND(JOAKIM!F7=F7,JOAKIM!G7=G7),"Win","Lose") -> Lose | AE7: =IF(AND(OUVARSHI!F7=F7,OUVARSHI!G7=G7),"Win","Lose") -> Lose | AF7: =IF(AND(STEPHAN!F7=F7,STEPHAN!G7=G7),"Win","Lose") -> Lose | AG7: =IF(AND(IRFAAN!F9=F9,IRFAAN!G9=G9),"Win","Lose") -> Lose | AH7: =IF(AND(ERVIN!F9=F9,ERVIN!G9=G9),"Win","Lose") -> Lose | AI7: =IF(AND(NOEMIE!F9=F9,NOEMIE!G9=G9),"Win","Lose") -> Lose | AJ7: =IF(AND(ISFAAQ!F7=F7,ISFAAQ!G7=G7),"Win","Lose") -> Win | AK7: =IF(AND(AHMAD!F7=F7,AHMAD!G7=G7),"Win","Lose") -> Lose | AL7: =IF(AND(PARIKSHIT!F7=F7,PARIKSHIT!G7=G7),"Win","Lose") -> Win | AM7: =IF(AND(JAYA!F7=F7,JAYA!G7=G7),"Win","Lose") -> Lose | AN7: =IF(AND(Elodie!F7=F7,Elodie!G7=G7),"Win","Lose") -> Lose | AO7: =IF(AND(RAVINDRA!F7=F7,RAVINDRA!G7=G7),"Win","Lose") -> Win | AP7: =IF(AND(Jessen!F7=F7,Jessen!G7=G7),"Win","Lose") -> Lose | AQ7: =IF(AND(Annavi!F7=F7,Annavi!G7=G7),"Win","Lose") -> Lose | AR7: =IF(AND(LUDOVIC!F7=F7,LUDOVIC!G7=G7),"Win","Lose") -> Win | AS7: =IF(AND(Nathalie!F7=F7,Nathalie!G7=G7),"Win","Lose") -> Lose | AT7: =IF(AND(Akshay!F7=F7,Akshay!G7=G7),"Win","Lose") -> Lose | AU7: =IF(AND(Bavish!F7=F7,Bavish!G7=G7),"Win","Lose") -> Lose | AV7: =IF(AND(Itish!F7=F7,Itish!G7=G7),"Win","Lose") -> Lose | AW7: =IF(AND(Oumar!F7=F7,Oumar!G7=G7),"Win","Lose") -> Lose | AX7: =IF(AND(Kesh!F7=F7,Kesh!G7=G7),"Win","Lose") -> Lose | AY7: =IF(AND(ADHISH!F7=F7,ADHISH!G7=G7),"Win","Lose") -> Win | AZ7: =IF(AND(Vishnee!F7=F7,Vishnee!G7=G7),"Win","Lose") -> Lose | BA7: =IF(AND(Sebastien!F7=F7,Sebastien!G7=G7),"Win","Lose") -> Lose | BB7: =IF(AND(Soneea!F7=F7,Soneea!G7=G7),"Win","Lose") -> Lose | BC7: =IF(AND(Geraldine!F7=F7,Geraldine!G7=G7),"Win","Lose") -> Lose | BD7: =IF(AND(Chaya!F7=F7,Chaya!G7=G7),"Win","Lose") -> Win | BE7: =IF(AND(Reshmi!F7=F7,Reshmi!G7=G7),"Win","Lose") -> Win
A8: 3 | B8: Fri | C8: Jun 12, 2026 | D8: 0.79166667 | E8: Canada | H8: Bosnia and Herzegovina | I8: =IF(AND(RYAN!F8=F8,RYAN!G8=G8),"Win","Lose") -> Lose | J8: =IF(AND(JONATHAN!F8=F8,JONATHAN!G8=G8),"Win","Lose") -> Lose | K8: =IF(AND(RAADIN!F8=F8,RAADIN!G8=G8),"Win","Lose") -> Lose | L8: =IF(AND(TANIA!F8=F8,TANIA!G8=G8),"Win","Lose") -> Lose | M8: =IF(AND(JEFF!F8=F8,JEFF!G8=G8),"Win","Lose") -> Lose | N8: =IF(AND(LUW!F8=F8,LUW!G8=G8),"Win","Lose") -> Lose | O8: =IF(AND(ASHRAF!F8=F8,ASHRAF!G8=G8),"Win","Lose") -> Lose | P8: =IF(AND(NAOMI!F8=F8,NAOMI!G8=G8),"Win","Lose") -> Lose | Q8: =IF(AND(CHARLENE!F8=F8,CHARLENE!G8=G8),"Win","Lose") -> Lose | R8: =IF(AND(VALERIE!F8=F8,VALERIE!G8=G8),"Win","Lose") -> Lose | S8: =IF(AND(KESHAV!F8=F8,KESHAV!G8=G8),"Win","Lose") -> Lose | T8: =IF(AND(MOHNISH!F8=F8,MOHNISH!G8=G8),"Win","Lose") -> Lose | U8: =IF(AND(NICOLAS!F8=F8,NICOLAS!G8=G8),"Win","Lose") -> Lose | V8: =IF(AND(JULIEN!F8=F8,JULIEN!G8=G8),"Win","Lose") -> Lose | W8: =IF(AND(ANDREW!F8=F8,ANDREW!G8=G8),"Win","Lose") -> Lose | X8: =IF(AND(JENNA!F8=F8,JENNA!G8=G8),"Win","Lose") -> Lose | Y8: =IF(AND(JANISH!F8=F8,JANISH!G8=G8),"Win","Lose") -> Lose | Z8: =IF(AND(SANDRASEN!F8=F8,SANDRASEN!G8=G8),"Win","Lose") -> Lose | AA8: =IF(AND(JESSY!F8=F8,JESSY!G8=G8),"Win","Lose") -> Lose | AB8: =IF(AND(PRASHANT!F8=F8,PRASHANT!G8=G8),"Win","Lose") -> Lose | AC8: =IF(AND(GEETIKA!F8=F8,GEETIKA!G8=G8),"Win","Lose") -> Lose | AD8: =IF(AND(JOAKIM!F8=F8,JOAKIM!G8=G8),"Win","Lose") -> Lose | AE8: =IF(AND(OUVARSHI!F8=F8,OUVARSHI!G8=G8),"Win","Lose") -> Lose | AF8: =IF(AND(STEPHAN!F8=F8,STEPHAN!G8=G8),"Win","Lose") -> Lose | AG8: =IF(AND(IRFAAN!F10=F10,IRFAAN!G10=G10),"Win","Lose") -> Lose | AH8: =IF(AND(ERVIN!F10=F10,ERVIN!G10=G10),"Win","Lose") -> Lose | AI8: =IF(AND(NOEMIE!F10=F10,NOEMIE!G10=G10),"Win","Lose") -> Lose | AJ8: =IF(AND(ISFAAQ!F8=F8,ISFAAQ!G8=G8),"Win","Lose") -> Lose | AK8: =IF(AND(AHMAD!F8=F8,AHMAD!G8=G8),"Win","Lose") -> Lose | AL8: =IF(AND(PARIKSHIT!F8=F8,PARIKSHIT!G8=G8),"Win","Lose") -> Lose | AM8: =IF(AND(JAYA!F8=F8,JAYA!G8=G8),"Win","Lose") -> Win | AN8: =IF(AND(Elodie!F8=F8,Elodie!G8=G8),"Win","Lose") -> Lose | AO8: =IF(AND(RAVINDRA!F8=F8,RAVINDRA!G8=G8),"Win","Lose") -> Lose | AP8: =IF(AND(Jessen!F8=F8,Jessen!G8=G8),"Win","Lose") -> Lose | AQ8: =IF(AND(Annavi!F8=F8,Annavi!G8=G8),"Win","Lose") -> Lose | AR8: =IF(AND(LUDOVIC!F8=F8,LUDOVIC!G8=G8),"Win","Lose") -> Lose | AS8: =IF(AND(Nathalie!F8=F8,Nathalie!G8=G8),"Win","Lose") -> Lose | AT8: =IF(AND(Akshay!F8=F8,Akshay!G8=G8),"Win","Lose") -> Lose | AU8: =IF(AND(Bavish!F8=F8,Bavish!G8=G8),"Win","Lose") -> Lose | AV8: =IF(AND(Itish!F8=F8,Itish!G8=G8),"Win","Lose") -> Lose | AW8: =IF(AND(Oumar!F8=F8,Oumar!G8=G8),"Win","Lose") -> Lose | AX8: =IF(AND(Kesh!F8=F8,Kesh!G8=G8),"Win","Lose") -> Lose | AY8: =IF(AND(ADHISH!F8=F8,ADHISH!G8=G8),"Win","Lose") -> Lose | AZ8: =IF(AND(Vishnee!F8=F8,Vishnee!G8=G8),"Win","Lose") -> Lose | BA8: =IF(AND(Sebastien!F8=F8,Sebastien!G8=G8),"Win","Lose") -> Lose | BB8: =IF(AND(Soneea!F8=F8,Soneea!G8=G8),"Win","Lose") -> Lose | BC8: =IF(AND(Geraldine!F8=F8,Geraldine!G8=G8),"Win","Lose") -> Lose | BD8: =IF(AND(Chaya!F8=F8,Chaya!G8=G8),"Win","Lose") -> Lose | BE8: =IF(AND(Reshmi!F8=F8,Reshmi!G8=G8),"Win","Lose") -> Lose
A9: 4 | B9: Sat | C9: Jun 13, 2026 | D9: 0.041666667 | E9: United States | H9: Paraguay | I9: =IF(AND(RYAN!F9=F9,RYAN!G9=G9),"Win","Lose") -> Lose | J9: =IF(AND(JONATHAN!F9=F9,JONATHAN!G9=G9),"Win","Lose") -> Lose | K9: =IF(AND(RAADIN!F9=F9,RAADIN!G9=G9),"Win","Lose") -> Lose | L9: =IF(AND(TANIA!F9=F9,TANIA!G9=G9),"Win","Lose") -> Lose | M9: =IF(AND(JEFF!F9=F9,JEFF!G9=G9),"Win","Lose") -> Lose | N9: =IF(AND(LUW!F9=F9,LUW!G9=G9),"Win","Lose") -> Lose | O9: =IF(AND(ASHRAF!F9=F9,ASHRAF!G9=G9),"Win","Lose") -> Lose | P9: =IF(AND(NAOMI!F9=F9,NAOMI!G9=G9),"Win","Lose") -> Lose | Q9: =IF(AND(CHARLENE!F9=F9,CHARLENE!G9=G9),"Win","Lose") -> Lose | R9: =IF(AND(VALERIE!F9=F9,VALERIE!G9=G9),"Win","Lose") -> Lose | S9: =IF(AND(KESHAV!F9=F9,KESHAV!G9=G9),"Win","Lose") -> Lose | T9: =IF(AND(MOHNISH!F9=F9,MOHNISH!G9=G9),"Win","Lose") -> Lose | U9: =IF(AND(NICOLAS!F9=F9,NICOLAS!G9=G9),"Win","Lose") -> Lose | V9: =IF(AND(JULIEN!F9=F9,JULIEN!G9=G9),"Win","Lose") -> Lose | W9: =IF(AND(ANDREW!F9=F9,ANDREW!G9=G9),"Win","Lose") -> Lose | X9: =IF(AND(JENNA!F9=F9,JENNA!G9=G9),"Win","Lose") -> Lose | Y9: =IF(AND(JANISH!F9=F9,JANISH!G9=G9),"Win","Lose") -> Lose | Z9: =IF(AND(SANDRASEN!F9=F9,SANDRASEN!G9=G9),"Win","Lose") -> Lose | AA9: =IF(AND(JESSY!F9=F9,JESSY!G9=G9),"Win","Lose") -> Lose | AB9: =IF(AND(PRASHANT!F9=F9,PRASHANT!G9=G9),"Win","Lose") -> Lose | AC9: =IF(AND(GEETIKA!F9=F9,GEETIKA!G9=G9),"Win","Lose") -> Lose | AD9: =IF(AND(JOAKIM!F9=F9,JOAKIM!G9=G9),"Win","Lose") -> Lose | AE9: =IF(AND(OUVARSHI!F9=F9,OUVARSHI!G9=G9),"Win","Lose") -> Lose | AF9: =IF(AND(STEPHAN!F9=F9,STEPHAN!G9=G9),"Win","Lose") -> Lose | AG9: =IF(AND(IRFAAN!F11=F11,IRFAAN!G11=G11),"Win","Lose") -> Lose | AH9: =IF(AND(ERVIN!F11=F11,ERVIN!G11=G11),"Win","Lose") -> Lose | AI9: =IF(AND(NOEMIE!F11=F11,NOEMIE!G11=G11),"Win","Lose") -> Lose | AJ9: =IF(AND(ISFAAQ!F9=F9,ISFAAQ!G9=G9),"Win","Lose") -> Lose | AK9: =IF(AND(AHMAD!F9=F9,AHMAD!G9=G9),"Win","Lose") -> Lose | AL9: =IF(AND(PARIKSHIT!F9=F9,PARIKSHIT!G9=G9),"Win","Lose") -> Lose | AM9: =IF(AND(JAYA!F9=F9,JAYA!G9=G9),"Win","Lose") -> Lose | AN9: =IF(AND(Elodie!F9=F9,Elodie!G9=G9),"Win","Lose") -> Lose | AO9: =IF(AND(RAVINDRA!F9=F9,RAVINDRA!G9=G9),"Win","Lose") -> Lose | AP9: =IF(AND(Jessen!F9=F9,Jessen!G9=G9),"Win","Lose") -> Lose | AQ9: =IF(AND(Annavi!F9=F9,Annavi!G9=G9),"Win","Lose") -> Lose | AR9: =IF(AND(LUDOVIC!F9=F9,LUDOVIC!G9=G9),"Win","Lose") -> Lose | AS9: =IF(AND(Nathalie!F9=F9,Nathalie!G9=G9),"Win","Lose") -> Lose | AT9: =IF(AND(Akshay!F9=F9,Akshay!G9=G9),"Win","Lose") -> Lose | AU9: =IF(AND(Bavish!F9=F9,Bavish!G9=G9),"Win","Lose") -> Lose | AV9: =IF(AND(Itish!F9=F9,Itish!G9=G9),"Win","Lose") -> Lose | AW9: =IF(AND(Oumar!F9=F9,Oumar!G9=G9),"Win","Lose") -> Lose | AX9: =IF(AND(Kesh!F9=F9,Kesh!G9=G9),"Win","Lose") -> Lose | AY9: =IF(AND(ADHISH!F9=F9,ADHISH!G9=G9),"Win","Lose") -> Lose | AZ9: =IF(AND(Vishnee!F9=F9,Vishnee!G9=G9),"Win","Lose") -> Lose | BA9: =IF(AND(Sebastien!F9=F9,Sebastien!G9=G9),"Win","Lose") -> Lose | BB9: =IF(AND(Soneea!F9=F9,Soneea!G9=G9),"Win","Lose") -> Lose | BC9: =IF(AND(Geraldine!F9=F9,Geraldine!G9=G9),"Win","Lose") -> Lose | BD9: =IF(AND(Chaya!F9=F9,Chaya!G9=G9),"Win","Lose") -> Lose | BE9: =IF(AND(Reshmi!F9=F9,Reshmi!G9=G9),"Win","Lose") -> Lose
A10: 5 | B10: Sun | C10: Jun 14, 2026 | D10: 0.041666667 | E10: Haiti | H10: Scotland | I10: =IF(AND(RYAN!F10=F10,RYAN!G10=G10),"Win","Lose") -> Lose | J10: =IF(AND(JONATHAN!F10=F10,JONATHAN!G10=G10),"Win","Lose") -> Lose | K10: =IF(AND(RAADIN!F10=F10,RAADIN!G10=G10),"Win","Lose") -> Lose | L10: =IF(AND(TANIA!F10=F10,TANIA!G10=G10),"Win","Lose") -> Lose | M10: =IF(AND(JEFF!F10=F10,JEFF!G10=G10),"Win","Lose") -> Lose | N10: =IF(AND(LUW!F10=F10,LUW!G10=G10),"Win","Lose") -> Lose | O10: =IF(AND(ASHRAF!F10=F10,ASHRAF!G10=G10),"Win","Lose") -> Lose | P10: =IF(AND(NAOMI!F10=F10,NAOMI!G10=G10),"Win","Lose") -> Lose | Q10: =IF(AND(CHARLENE!F10=F10,CHARLENE!G10=G10),"Win","Lose") -> Lose | R10: =IF(AND(VALERIE!F10=F10,VALERIE!G10=G10),"Win","Lose") -> Lose | S10: =IF(AND(KESHAV!F10=F10,KESHAV!G10=G10),"Win","Lose") -> Lose | T10: =IF(AND(MOHNISH!F10=F10,MOHNISH!G10=G10),"Win","Lose") -> Lose | U10: =IF(AND(NICOLAS!F10=F10,NICOLAS!G10=G10),"Win","Lose") -> Lose | V10: =IF(AND(JULIEN!F10=F10,JULIEN!G10=G10),"Win","Lose") -> Lose | W10: =IF(AND(ANDREW!F10=F10,ANDREW!G10=G10),"Win","Lose") -> Lose | X10: =IF(AND(JENNA!F10=F10,JENNA!G10=G10),"Win","Lose") -> Lose | Y10: =IF(AND(JANISH!F10=F10,JANISH!G10=G10),"Win","Lose") -> Lose | Z10: =IF(AND(SANDRASEN!F10=F10,SANDRASEN!G10=G10),"Win","Lose") -> Lose | AA10: =IF(AND(JESSY!F10=F10,JESSY!G10=G10),"Win","Lose") -> Lose | AB10: =IF(AND(PRASHANT!F10=F10,PRASHANT!G10=G10),"Win","Lose") -> Lose | AC10: =IF(AND(GEETIKA!F10=F10,GEETIKA!G10=G10),"Win","Lose") -> Lose | AD10: =IF(AND(JOAKIM!F10=F10,JOAKIM!G10=G10),"Win","Lose") -> Lose | AE10: =IF(AND(OUVARSHI!F10=F10,OUVARSHI!G10=G10),"Win","Lose") -> Lose | AF10: =IF(AND(STEPHAN!F10=F10,STEPHAN!G10=G10),"Win","Lose") -> Lose | AG10: =IF(AND(IRFAAN!F12=F12,IRFAAN!G12=G12),"Win","Lose") -> Lose | AH10: =IF(AND(ERVIN!F12=F12,ERVIN!G12=G12),"Win","Lose") -> Lose | AI10: =IF(AND(NOEMIE!F12=F12,NOEMIE!G12=G12),"Win","Lose") -> Lose | AJ10: =IF(AND(ISFAAQ!F10=F10,ISFAAQ!G10=G10),"Win","Lose") -> Lose | AK10: =IF(AND(AHMAD!F10=F10,AHMAD!G10=G10),"Win","Lose") -> Lose | AL10: =IF(AND(PARIKSHIT!F10=F10,PARIKSHIT!G10=G10),"Win","Lose") -> Lose | AM10: =IF(AND(JAYA!F10=F10,JAYA!G10=G10),"Win","Lose") -> Lose | AN10: =IF(AND(Elodie!F10=F10,Elodie!G10=G10),"Win","Lose") -> Lose | AO10: =IF(AND(RAVINDRA!F10=F10,RAVINDRA!G10=G10),"Win","Lose") -> Lose | AP10: =IF(AND(Jessen!F10=F10,Jessen!G10=G10),"Win","Lose") -> Lose | AQ10: =IF(AND(Annavi!F10=F10,Annavi!G10=G10),"Win","Lose") -> Lose | AR10: =IF(AND(LUDOVIC!F10=F10,LUDOVIC!G10=G10),"Win","Lose") -> Lose | AS10: =IF(AND(Nathalie!F10=F10,Nathalie!G10=G10),"Win","Lose") -> Lose | AT10: =IF(AND(Akshay!F10=F10,Akshay!G10=G10),"Win","Lose") -> Lose | AU10: =IF(AND(Bavish!F10=F10,Bavish!G10=G10),"Win","Lose") -> Lose | AV10: =IF(AND(Itish!F10=F10,Itish!G10=G10),"Win","Lose") -> Lose | AW10: =IF(AND(Oumar!F10=F10,Oumar!G10=G10),"Win","Lose") -> Lose | AX10: =IF(AND(Kesh!F10=F10,Kesh!G10=G10),"Win","Lose") -> Lose | AY10: =IF(AND(ADHISH!F10=F10,ADHISH!G10=G10),"Win","Lose") -> Lose | AZ10: =IF(AND(Vishnee!F10=F10,Vishnee!G10=G10),"Win","Lose") -> Lose | BA10: =IF(AND(Sebastien!F10=F10,Sebastien!G10=G10),"Win","Lose") -> Lose | BB10: =IF(AND(Soneea!F10=F10,Soneea!G10=G10),"Win","Lose") -> Lose | BC10: =IF(AND(Geraldine!F10=F10,Geraldine!G10=G10),"Win","Lose") -> Lose | BD10: =IF(AND(Chaya!F10=F10,Chaya!G10=G10),"Win","Lose") -> Lose | BE10: =IF(AND(Reshmi!F10=F10,Reshmi!G10=G10),"Win","Lose") -> Lose
A11: 6 | B11: Sun | C11: Jun 14, 2026 | D11: 0.16666667 | E11: Australia | H11: Turkey | I11: =IF(AND(RYAN!F11=F11,RYAN!G11=G11),"Win","Lose") -> Lose | J11: =IF(AND(JONATHAN!F11=F11,JONATHAN!G11=G11),"Win","Lose") -> Lose | K11: =IF(AND(RAADIN!F11=F11,RAADIN!G11=G11),"Win","Lose") -> Lose | L11: =IF(AND(TANIA!F11=F11,TANIA!G11=G11),"Win","Lose") -> Lose | M11: =IF(AND(JEFF!F11=F11,JEFF!G11=G11),"Win","Lose") -> Lose | N11: =IF(AND(LUW!F11=F11,LUW!G11=G11),"Win","Lose") -> Lose | O11: =IF(AND(ASHRAF!F11=F11,ASHRAF!G11=G11),"Win","Lose") -> Lose | P11: =IF(AND(NAOMI!F11=F11,NAOMI!G11=G11),"Win","Lose") -> Lose | Q11: =IF(AND(CHARLENE!F11=F11,CHARLENE!G11=G11),"Win","Lose") -> Lose | R11: =IF(AND(VALERIE!F11=F11,VALERIE!G11=G11),"Win","Lose") -> Lose | S11: =IF(AND(KESHAV!F11=F11,KESHAV!G11=G11),"Win","Lose") -> Lose | T11: =IF(AND(MOHNISH!F11=F11,MOHNISH!G11=G11),"Win","Lose") -> Lose | U11: =IF(AND(NICOLAS!F11=F11,NICOLAS!G11=G11),"Win","Lose") -> Lose | V11: =IF(AND(JULIEN!F11=F11,JULIEN!G11=G11),"Win","Lose") -> Lose | W11: =IF(AND(ANDREW!F11=F11,ANDREW!G11=G11),"Win","Lose") -> Lose | X11: =IF(AND(JENNA!F11=F11,JENNA!G11=G11),"Win","Lose") -> Lose | Y11: =IF(AND(JANISH!F11=F11,JANISH!G11=G11),"Win","Lose") -> Win | Z11: =IF(AND(SANDRASEN!F11=F11,SANDRASEN!G11=G11),"Win","Lose") -> Lose | AA11: =IF(AND(JESSY!F11=F11,JESSY!G11=G11),"Win","Lose") -> Lose | AB11: =IF(AND(PRASHANT!F11=F11,PRASHANT!G11=G11),"Win","Lose") -> Lose | AC11: =IF(AND(GEETIKA!F11=F11,GEETIKA!G11=G11),"Win","Lose") -> Lose | AD11: =IF(AND(JOAKIM!F11=F11,JOAKIM!G11=G11),"Win","Lose") -> Lose | AE11: =IF(AND(OUVARSHI!F11=F11,OUVARSHI!G11=G11),"Win","Lose") -> Lose | AF11: =IF(AND(STEPHAN!F11=F11,STEPHAN!G11=G11),"Win","Lose") -> Lose | AG11: =IF(AND(IRFAAN!F13=F13,IRFAAN!G13=G13),"Win","Lose") -> Lose | AH11: =IF(AND(ERVIN!F13=F13,ERVIN!G13=G13),"Win","Lose") -> Lose | AI11: =IF(AND(NOEMIE!F13=F13,NOEMIE!G13=G13),"Win","Lose") -> Lose | AJ11: =IF(AND(ISFAAQ!F11=F11,ISFAAQ!G11=G11),"Win","Lose") -> Lose | AK11: =IF(AND(AHMAD!F11=F11,AHMAD!G11=G11),"Win","Lose") -> Lose | AL11: =IF(AND(PARIKSHIT!F11=F11,PARIKSHIT!G11=G11),"Win","Lose") -> Lose | AM11: =IF(AND(JAYA!F11=F11,JAYA!G11=G11),"Win","Lose") -> Lose | AN11: =IF(AND(Elodie!F11=F11,Elodie!G11=G11),"Win","Lose") -> Win | AO11: =IF(AND(RAVINDRA!F11=F11,RAVINDRA!G11=G11),"Win","Lose") -> Lose | AP11: =IF(AND(Jessen!F11=F11,Jessen!G11=G11),"Win","Lose") -> Lose | AQ11: =IF(AND(Annavi!F11=F11,Annavi!G11=G11),"Win","Lose") -> Lose | AR11: =IF(AND(LUDOVIC!F11=F11,LUDOVIC!G11=G11),"Win","Lose") -> Lose | AS11: =IF(AND(Nathalie!F11=F11,Nathalie!G11=G11),"Win","Lose") -> Lose | AT11: =IF(AND(Akshay!F11=F11,Akshay!G11=G11),"Win","Lose") -> Lose | AU11: =IF(AND(Bavish!F11=F11,Bavish!G11=G11),"Win","Lose") -> Lose | AV11: =IF(AND(Itish!F11=F11,Itish!G11=G11),"Win","Lose") -> Lose | AW11: =IF(AND(Oumar!F11=F11,Oumar!G11=G11),"Win","Lose") -> Lose | AX11: =IF(AND(Kesh!F11=F11,Kesh!G11=G11),"Win","Lose") -> Lose | AY11: =IF(AND(ADHISH!F11=F11,ADHISH!G11=G11),"Win","Lose") -> Lose | AZ11: =IF(AND(Vishnee!F11=F11,Vishnee!G11=G11),"Win","Lose") -> Lose | BA11: =IF(AND(Sebastien!F11=F11,Sebastien!G11=G11),"Win","Lose") -> Lose | BB11: =IF(AND(Soneea!F11=F11,Soneea!G11=G11),"Win","Lose") -> Lose | BC11: =IF(AND(Geraldine!F11=F11,Geraldine!G11=G11),"Win","Lose") -> Lose | BD11: =IF(AND(Chaya!F11=F11,Chaya!G11=G11),"Win","Lose") -> Lose | BE11: =IF(AND(Reshmi!F11=F11,Reshmi!G11=G11),"Win","Lose") -> Lose
A12: 7 | B12: Sat | C12: Jun 13, 2026 | D12: 0.91666667 | E12: Brazil | H12: Morocco | I12: =IF(AND(RYAN!F12=F12,RYAN!G12=G12),"Win","Lose") -> Lose | J12: =IF(AND(JONATHAN!F12=F12,JONATHAN!G12=G12),"Win","Lose") -> Lose | K12: =IF(AND(RAADIN!F12=F12,RAADIN!G12=G12),"Win","Lose") -> Lose | L12: =IF(AND(TANIA!F12=F12,TANIA!G12=G12),"Win","Lose") -> Lose | M12: =IF(AND(JEFF!F12=F12,JEFF!G12=G12),"Win","Lose") -> Lose | N12: =IF(AND(LUW!F12=F12,LUW!G12=G12),"Win","Lose") -> Lose | O12: =IF(AND(ASHRAF!F12=F12,ASHRAF!G12=G12),"Win","Lose") -> Lose | P12: =IF(AND(NAOMI!F12=F12,NAOMI!G12=G12),"Win","Lose") -> Lose | Q12: =IF(AND(CHARLENE!F12=F12,CHARLENE!G12=G12),"Win","Lose") -> Lose | R12: =IF(AND(VALERIE!F12=F12,VALERIE!G12=G12),"Win","Lose") -> Lose | S12: =IF(AND(KESHAV!F12=F12,KESHAV!G12=G12),"Win","Lose") -> Lose | T12: =IF(AND(MOHNISH!F12=F12,MOHNISH!G12=G12),"Win","Lose") -> Lose | U12: =IF(AND(NICOLAS!F12=F12,NICOLAS!G12=G12),"Win","Lose") -> Lose | V12: =IF(AND(JULIEN!F12=F12,JULIEN!G12=G12),"Win","Lose") -> Lose | W12: =IF(AND(ANDREW!F12=F12,ANDREW!G12=G12),"Win","Lose") -> Lose | X12: =IF(AND(JENNA!F12=F12,JENNA!G12=G12),"Win","Lose") -> Lose | Y12: =IF(AND(JANISH!F12=F12,JANISH!G12=G12),"Win","Lose") -> Lose | Z12: =IF(AND(SANDRASEN!F12=F12,SANDRASEN!G12=G12),"Win","Lose") -> Lose | AA12: =IF(AND(JESSY!F12=F12,JESSY!G12=G12),"Win","Lose") -> Lose | AB12: =IF(AND(PRASHANT!F12=F12,PRASHANT!G12=G12),"Win","Lose") -> Lose | AC12: =IF(AND(GEETIKA!F12=F12,GEETIKA!G12=G12),"Win","Lose") -> Lose | AD12: =IF(AND(JOAKIM!F12=F12,JOAKIM!G12=G12),"Win","Lose") -> Lose | AE12: =IF(AND(OUVARSHI!F12=F12,OUVARSHI!G12=G12),"Win","Lose") -> Lose | AF12: =IF(AND(STEPHAN!F12=F12,STEPHAN!G12=G12),"Win","Lose") -> Lose | AG12: =IF(AND(IRFAAN!F14=F14,IRFAAN!G14=G14),"Win","Lose") -> Lose | AH12: =IF(AND(ERVIN!F14=F14,ERVIN!G14=G14),"Win","Lose") -> Lose | AI12: =IF(AND(NOEMIE!F14=F14,NOEMIE!G14=G14),"Win","Lose") -> Lose | AJ12: =IF(AND(ISFAAQ!F12=F12,ISFAAQ!G12=G12),"Win","Lose") -> Lose | AK12: =IF(AND(AHMAD!F12=F12,AHMAD!G12=G12),"Win","Lose") -> Lose | AL12: =IF(AND(PARIKSHIT!F12=F12,PARIKSHIT!G12=G12),"Win","Lose") -> Lose | AM12: =IF(AND(JAYA!F12=F12,JAYA!G12=G12),"Win","Lose") -> Lose | AN12: =IF(AND(Elodie!F12=F12,Elodie!G12=G12),"Win","Lose") -> Lose | AO12: =IF(AND(RAVINDRA!F12=F12,RAVINDRA!G12=G12),"Win","Lose") -> Lose | AP12: =IF(AND(Jessen!F12=F12,Jessen!G12=G12),"Win","Lose") -> Lose | AQ12: =IF(AND(Annavi!F12=F12,Annavi!G12=G12),"Win","Lose") -> Lose | AR12: =IF(AND(LUDOVIC!F12=F12,LUDOVIC!G12=G12),"Win","Lose") -> Lose | AS12: =IF(AND(Nathalie!F12=F12,Nathalie!G12=G12),"Win","Lose") -> Lose | AT12: =IF(AND(Akshay!F12=F12,Akshay!G12=G12),"Win","Lose") -> Lose | AU12: =IF(AND(Bavish!F12=F12,Bavish!G12=G12),"Win","Lose") -> Lose | AV12: =IF(AND(Itish!F12=F12,Itish!G12=G12),"Win","Lose") -> Lose | AW12: =IF(AND(Oumar!F12=F12,Oumar!G12=G12),"Win","Lose") -> Lose | AX12: =IF(AND(Kesh!F12=F12,Kesh!G12=G12),"Win","Lose") -> Lose | AY12: =IF(AND(ADHISH!F12=F12,ADHISH!G12=G12),"Win","Lose") -> Lose | AZ12: =IF(AND(Vishnee!F12=F12,Vishnee!G12=G12),"Win","Lose") -> Lose | BA12: =IF(AND(Sebastien!F12=F12,Sebastien!G12=G12),"Win","Lose") -> Lose | BB12: =IF(AND(Soneea!F12=F12,Soneea!G12=G12),"Win","Lose") -> Lose | BC12: =IF(AND(Geraldine!F12=F12,Geraldine!G12=G12),"Win","Lose") -> Lose | BD12: =IF(AND(Chaya!F12=F12,Chaya!G12=G12),"Win","Lose") -> Lose | BE12: =IF(AND(Reshmi!F12=F12,Reshmi!G12=G12),"Win","Lose") -> Lose
A13: 8 | B13: Sat | C13: Jun 13, 2026 | D13: 0.79166667 | E13: Qatar | H13: Switzerland | I13: =IF(AND(RYAN!F13=F13,RYAN!G13=G13),"Win","Lose") -> Lose | J13: =IF(AND(JONATHAN!F13=F13,JONATHAN!G13=G13),"Win","Lose") -> Lose | K13: =IF(AND(RAADIN!F13=F13,RAADIN!G13=G13),"Win","Lose") -> Lose | L13: =IF(AND(TANIA!F13=F13,TANIA!G13=G13),"Win","Lose") -> Lose | M13: =IF(AND(JEFF!F13=F13,JEFF!G13=G13),"Win","Lose") -> Lose | N13: =IF(AND(LUW!F13=F13,LUW!G13=G13),"Win","Lose") -> Lose | O13: =IF(AND(ASHRAF!F13=F13,ASHRAF!G13=G13),"Win","Lose") -> Lose | P13: =IF(AND(NAOMI!F13=F13,NAOMI!G13=G13),"Win","Lose") -> Lose | Q13: =IF(AND(CHARLENE!F13=F13,CHARLENE!G13=G13),"Win","Lose") -> Lose | R13: =IF(AND(VALERIE!F13=F13,VALERIE!G13=G13),"Win","Lose") -> Lose | S13: =IF(AND(KESHAV!F13=F13,KESHAV!G13=G13),"Win","Lose") -> Lose | T13: =IF(AND(MOHNISH!F13=F13,MOHNISH!G13=G13),"Win","Lose") -> Lose | U13: =IF(AND(NICOLAS!F13=F13,NICOLAS!G13=G13),"Win","Lose") -> Lose | V13: =IF(AND(JULIEN!F13=F13,JULIEN!G13=G13),"Win","Lose") -> Lose | W13: =IF(AND(ANDREW!F13=F13,ANDREW!G13=G13),"Win","Lose") -> Lose | X13: =IF(AND(JENNA!F13=F13,JENNA!G13=G13),"Win","Lose") -> Lose | Y13: =IF(AND(JANISH!F13=F13,JANISH!G13=G13),"Win","Lose") -> Lose | Z13: =IF(AND(SANDRASEN!F13=F13,SANDRASEN!G13=G13),"Win","Lose") -> Lose | AA13: =IF(AND(JESSY!F13=F13,JESSY!G13=G13),"Win","Lose") -> Lose | AB13: =IF(AND(PRASHANT!F13=F13,PRASHANT!G13=G13),"Win","Lose") -> Lose | AC13: =IF(AND(GEETIKA!F13=F13,GEETIKA!G13=G13),"Win","Lose") -> Lose | AD13: =IF(AND(JOAKIM!F13=F13,JOAKIM!G13=G13),"Win","Lose") -> Lose | AE13: =IF(AND(OUVARSHI!F13=F13,OUVARSHI!G13=G13),"Win","Lose") -> Lose | AF13: =IF(AND(STEPHAN!F13=F13,STEPHAN!G13=G13),"Win","Lose") -> Lose | AG13: =IF(AND(IRFAAN!F15=F15,IRFAAN!G15=G15),"Win","Lose") -> Lose | AH13: =IF(AND(ERVIN!F15=F15,ERVIN!G15=G15),"Win","Lose") -> Lose | AI13: =IF(AND(NOEMIE!F15=F15,NOEMIE!G15=G15),"Win","Lose") -> Lose | AJ13: =IF(AND(ISFAAQ!F13=F13,ISFAAQ!G13=G13),"Win","Lose") -> Lose | AK13: =IF(AND(AHMAD!F13=F13,AHMAD!G13=G13),"Win","Lose") -> Lose | AL13: =IF(AND(PARIKSHIT!F13=F13,PARIKSHIT!G13=G13),"Win","Lose") -> Lose | AM13: =IF(AND(JAYA!F13=F13,JAYA!G13=G13),"Win","Lose") -> Lose | AN13: =IF(AND(Elodie!F13=F13,Elodie!G13=G13),"Win","Lose") -> Lose | AO13: =IF(AND(RAVINDRA!F13=F13,RAVINDRA!G13=G13),"Win","Lose") -> Lose | AP13: =IF(AND(Jessen!F13=F13,Jessen!G13=G13),"Win","Lose") -> Lose | AQ13: =IF(AND(Annavi!F13=F13,Annavi!G13=G13),"Win","Lose") -> Lose | AR13: =IF(AND(LUDOVIC!F13=F13,LUDOVIC!G13=G13),"Win","Lose") -> Lose | AS13: =IF(AND(Nathalie!F13=F13,Nathalie!G13=G13),"Win","Lose") -> Lose | AT13: =IF(AND(Akshay!F13=F13,Akshay!G13=G13),"Win","Lose") -> Lose | AU13: =IF(AND(Bavish!F13=F13,Bavish!G13=G13),"Win","Lose") -> Lose | AV13: =IF(AND(Itish!F13=F13,Itish!G13=G13),"Win","Lose") -> Lose | AW13: =IF(AND(Oumar!F13=F13,Oumar!G13=G13),"Win","Lose") -> Lose | AX13: =IF(AND(Kesh!F13=F13,Kesh!G13=G13),"Win","Lose") -> Lose | AY13: =IF(AND(ADHISH!F13=F13,ADHISH!G13=G13),"Win","Lose") -> Lose | AZ13: =IF(AND(Vishnee!F13=F13,Vishnee!G13=G13),"Win","Lose") -> Lose | BA13: =IF(AND(Sebastien!F13=F13,Sebastien!G13=G13),"Win","Lose") -> Lose | BB13: =IF(AND(Soneea!F13=F13,Soneea!G13=G13),"Win","Lose") -> Lose | BC13: =IF(AND(Geraldine!F13=F13,Geraldine!G13=G13),"Win","Lose") -> Lose | BD13: =IF(AND(Chaya!F13=F13,Chaya!G13=G13),"Win","Lose") -> Lose | BE13: =IF(AND(Reshmi!F13=F13,Reshmi!G13=G13),"Win","Lose") -> Lose
A14: 9 | B14: Sun | C14: Jun 14, 2026 | D14: 0.95833333 | E14: Ivory Coast | H14: Ecuador | I14: =IF(AND(RYAN!F14=F14,RYAN!G14=G14),"Win","Lose") -> Lose | J14: =IF(AND(JONATHAN!F14=F14,JONATHAN!G14=G14),"Win","Lose") -> Lose | K14: =IF(AND(RAADIN!F14=F14,RAADIN!G14=G14),"Win","Lose") -> Lose | L14: =IF(AND(TANIA!F14=F14,TANIA!G14=G14),"Win","Lose") -> Lose | M14: =IF(AND(JEFF!F14=F14,JEFF!G14=G14),"Win","Lose") -> Lose | N14: =IF(AND(LUW!F14=F14,LUW!G14=G14),"Win","Lose") -> Lose | O14: =IF(AND(ASHRAF!F14=F14,ASHRAF!G14=G14),"Win","Lose") -> Lose | P14: =IF(AND(NAOMI!F14=F14,NAOMI!G14=G14),"Win","Lose") -> Lose | Q14: =IF(AND(CHARLENE!F14=F14,CHARLENE!G14=G14),"Win","Lose") -> Lose | R14: =IF(AND(VALERIE!F14=F14,VALERIE!G14=G14),"Win","Lose") -> Lose | S14: =IF(AND(KESHAV!F14=F14,KESHAV!G14=G14),"Win","Lose") -> Lose | T14: =IF(AND(MOHNISH!F14=F14,MOHNISH!G14=G14),"Win","Lose") -> Lose | U14: =IF(AND(NICOLAS!F14=F14,NICOLAS!G14=G14),"Win","Lose") -> Lose | V14: =IF(AND(JULIEN!F14=F14,JULIEN!G14=G14),"Win","Lose") -> Lose | W14: =IF(AND(ANDREW!F14=F14,ANDREW!G14=G14),"Win","Lose") -> Lose | X14: =IF(AND(JENNA!F14=F14,JENNA!G14=G14),"Win","Lose") -> Lose | Y14: =IF(AND(JANISH!F14=F14,JANISH!G14=G14),"Win","Lose") -> Lose | Z14: =IF(AND(SANDRASEN!F14=F14,SANDRASEN!G14=G14),"Win","Lose") -> Lose | AA14: =IF(AND(JESSY!F14=F14,JESSY!G14=G14),"Win","Lose") -> Lose | AB14: =IF(AND(PRASHANT!F14=F14,PRASHANT!G14=G14),"Win","Lose") -> Lose | AC14: =IF(AND(GEETIKA!F14=F14,GEETIKA!G14=G14),"Win","Lose") -> Lose | AD14: =IF(AND(JOAKIM!F14=F14,JOAKIM!G14=G14),"Win","Lose") -> Lose | AE14: =IF(AND(OUVARSHI!F14=F14,OUVARSHI!G14=G14),"Win","Lose") -> Win | AF14: =IF(AND(STEPHAN!F14=F14,STEPHAN!G14=G14),"Win","Lose") -> Lose | AG14: =IF(AND(IRFAAN!F16=F16,IRFAAN!G16=G16),"Win","Lose") -> Lose | AH14: =IF(AND(ERVIN!F16=F16,ERVIN!G16=G16),"Win","Lose") -> Lose | AI14: =IF(AND(NOEMIE!F16=F16,NOEMIE!G16=G16),"Win","Lose") -> Lose | AJ14: =IF(AND(ISFAAQ!F14=F14,ISFAAQ!G14=G14),"Win","Lose") -> Lose | AK14: =IF(AND(AHMAD!F14=F14,AHMAD!G14=G14),"Win","Lose") -> Lose | AL14: =IF(AND(PARIKSHIT!F14=F14,PARIKSHIT!G14=G14),"Win","Lose") -> Lose | AM14: =IF(AND(JAYA!F14=F14,JAYA!G14=G14),"Win","Lose") -> Lose | AN14: =IF(AND(Elodie!F14=F14,Elodie!G14=G14),"Win","Lose") -> Lose | AO14: =IF(AND(RAVINDRA!F14=F14,RAVINDRA!G14=G14),"Win","Lose") -> Lose | AP14: =IF(AND(Jessen!F14=F14,Jessen!G14=G14),"Win","Lose") -> Lose | AQ14: =IF(AND(Annavi!F14=F14,Annavi!G14=G14),"Win","Lose") -> Lose | AR14: =IF(AND(LUDOVIC!F14=F14,LUDOVIC!G14=G14),"Win","Lose") -> Lose | AS14: =IF(AND(Nathalie!F14=F14,Nathalie!G14=G14),"Win","Lose") -> Lose | AT14: =IF(AND(Akshay!F14=F14,Akshay!G14=G14),"Win","Lose") -> Lose | AU14: =IF(AND(Bavish!F14=F14,Bavish!G14=G14),"Win","Lose") -> Lose | AV14: =IF(AND(Itish!F14=F14,Itish!G14=G14),"Win","Lose") -> Lose | AW14: =IF(AND(Oumar!F14=F14,Oumar!G14=G14),"Win","Lose") -> Lose | AX14: =IF(AND(Kesh!F14=F14,Kesh!G14=G14),"Win","Lose") -> Lose | AY14: =IF(AND(ADHISH!F14=F14,ADHISH!G14=G14),"Win","Lose") -> Lose | AZ14: =IF(AND(Vishnee!F14=F14,Vishnee!G14=G14),"Win","Lose") -> Lose | BA14: =IF(AND(Sebastien!F14=F14,Sebastien!G14=G14),"Win","Lose") -> Lose | BB14: =IF(AND(Soneea!F14=F14,Soneea!G14=G14),"Win","Lose") -> Lose | BC14: =IF(AND(Geraldine!F14=F14,Geraldine!G14=G14),"Win","Lose") -> Lose | BD14: =IF(AND(Chaya!F14=F14,Chaya!G14=G14),"Win","Lose") -> Lose | BE14: =IF(AND(Reshmi!F14=F14,Reshmi!G14=G14),"Win","Lose") -> Lose
A15: 10 | B15: Sun | C15: Jun 14, 2026 | D15: 0.70833333 | E15: Germany | H15: Curaçao | I15: =IF(AND(RYAN!F15=F15,RYAN!G15=G15),"Win","Lose") -> Lose | J15: =IF(AND(JONATHAN!F15=F15,JONATHAN!G15=G15),"Win","Lose") -> Lose | K15: =IF(AND(RAADIN!F15=F15,RAADIN!G15=G15),"Win","Lose") -> Lose | L15: =IF(AND(TANIA!F15=F15,TANIA!G15=G15),"Win","Lose") -> Lose | M15: =IF(AND(JEFF!F15=F15,JEFF!G15=G15),"Win","Lose") -> Lose | N15: =IF(AND(LUW!F15=F15,LUW!G15=G15),"Win","Lose") -> Lose | O15: =IF(AND(ASHRAF!F15=F15,ASHRAF!G15=G15),"Win","Lose") -> Lose | P15: =IF(AND(NAOMI!F15=F15,NAOMI!G15=G15),"Win","Lose") -> Lose | Q15: =IF(AND(CHARLENE!F15=F15,CHARLENE!G15=G15),"Win","Lose") -> Lose | R15: =IF(AND(VALERIE!F15=F15,VALERIE!G15=G15),"Win","Lose") -> Lose | S15: =IF(AND(KESHAV!F15=F15,KESHAV!G15=G15),"Win","Lose") -> Lose | T15: =IF(AND(MOHNISH!F15=F15,MOHNISH!G15=G15),"Win","Lose") -> Lose | U15: =IF(AND(NICOLAS!F15=F15,NICOLAS!G15=G15),"Win","Lose") -> Lose | V15: =IF(AND(JULIEN!F15=F15,JULIEN!G15=G15),"Win","Lose") -> Lose | W15: =IF(AND(ANDREW!F15=F15,ANDREW!G15=G15),"Win","Lose") -> Lose | X15: =IF(AND(JENNA!F15=F15,JENNA!G15=G15),"Win","Lose") -> Lose | Y15: =IF(AND(JANISH!F15=F15,JANISH!G15=G15),"Win","Lose") -> Lose | Z15: =IF(AND(SANDRASEN!F15=F15,SANDRASEN!G15=G15),"Win","Lose") -> Lose | AA15: =IF(AND(JESSY!F15=F15,JESSY!G15=G15),"Win","Lose") -> Lose | AB15: =IF(AND(PRASHANT!F15=F15,PRASHANT!G15=G15),"Win","Lose") -> Lose | AC15: =IF(AND(GEETIKA!F15=F15,GEETIKA!G15=G15),"Win","Lose") -> Lose | AD15: =IF(AND(JOAKIM!F15=F15,JOAKIM!G15=G15),"Win","Lose") -> Lose | AE15: =IF(AND(OUVARSHI!F15=F15,OUVARSHI!G15=G15),"Win","Lose") -> Lose | AF15: =IF(AND(STEPHAN!F15=F15,STEPHAN!G15=G15),"Win","Lose") -> Lose | AG15: =IF(AND(IRFAAN!F17=F17,IRFAAN!G17=G17),"Win","Lose") -> Lose | AH15: =IF(AND(ERVIN!F17=F17,ERVIN!G17=G17),"Win","Lose") -> Lose | AI15: =IF(AND(NOEMIE!F17=F17,NOEMIE!G17=G17),"Win","Lose") -> Lose | AJ15: =IF(AND(ISFAAQ!F15=F15,ISFAAQ!G15=G15),"Win","Lose") -> Lose | AK15: =IF(AND(AHMAD!F15=F15,AHMAD!G15=G15),"Win","Lose") -> Lose | AL15: =IF(AND(PARIKSHIT!F15=F15,PARIKSHIT!G15=G15),"Win","Lose") -> Lose | AM15: =IF(AND(JAYA!F15=F15,JAYA!G15=G15),"Win","Lose") -> Lose | AN15: =IF(AND(Elodie!F15=F15,Elodie!G15=G15),"Win","Lose") -> Lose | AO15: =IF(AND(RAVINDRA!F15=F15,RAVINDRA!G15=G15),"Win","Lose") -> Lose | AP15: =IF(AND(Jessen!F15=F15,Jessen!G15=G15),"Win","Lose") -> Lose | AQ15: =IF(AND(Annavi!F15=F15,Annavi!G15=G15),"Win","Lose") -> Lose | AR15: =IF(AND(LUDOVIC!F15=F15,LUDOVIC!G15=G15),"Win","Lose") -> Lose | AS15: =IF(AND(Nathalie!F15=F15,Nathalie!G15=G15),"Win","Lose") -> Lose | AT15: =IF(AND(Akshay!F15=F15,Akshay!G15=G15),"Win","Lose") -> Lose | AU15: =IF(AND(Bavish!F15=F15,Bavish!G15=G15),"Win","Lose") -> Lose | AV15: =IF(AND(Itish!F15=F15,Itish!G15=G15),"Win","Lose") -> Lose | AW15: =IF(AND(Oumar!F15=F15,Oumar!G15=G15),"Win","Lose") -> Lose | AX15: =IF(AND(Kesh!F15=F15,Kesh!G15=G15),"Win","Lose") -> Lose | AY15: =IF(AND(ADHISH!F15=F15,ADHISH!G15=G15),"Win","Lose") -> Lose | AZ15: =IF(AND(Vishnee!F15=F15,Vishnee!G15=G15),"Win","Lose") -> Lose | BA15: =IF(AND(Sebastien!F15=F15,Sebastien!G15=G15),"Win","Lose") -> Lose | BB15: =IF(AND(Soneea!F15=F15,Soneea!G15=G15),"Win","Lose") -> Lose | BC15: =IF(AND(Geraldine!F15=F15,Geraldine!G15=G15),"Win","Lose") -> Lose | BD15: =IF(AND(Chaya!F15=F15,Chaya!G15=G15),"Win","Lose") -> Lose | BE15: =IF(AND(Reshmi!F15=F15,Reshmi!G15=G15),"Win","Lose") -> Lose
A16: 11 | B16: Sun | C16: Jun 14, 2026 | D16: 0.83333333 | E16: Netherlands | H16: Japan | I16: =IF(AND(RYAN!F16=F16,RYAN!G16=G16),"Win","Lose") -> Lose | J16: =IF(AND(JONATHAN!F16=F16,JONATHAN!G16=G16),"Win","Lose") -> Lose | K16: =IF(AND(RAADIN!F16=F16,RAADIN!G16=G16),"Win","Lose") -> Lose | L16: =IF(AND(TANIA!F16=F16,TANIA!G16=G16),"Win","Lose") -> Lose | M16: =IF(AND(JEFF!F16=F16,JEFF!G16=G16),"Win","Lose") -> Lose | N16: =IF(AND(LUW!F16=F16,LUW!G16=G16),"Win","Lose") -> Lose | O16: =IF(AND(ASHRAF!F16=F16,ASHRAF!G16=G16),"Win","Lose") -> Lose | P16: =IF(AND(NAOMI!F16=F16,NAOMI!G16=G16),"Win","Lose") -> Lose | Q16: =IF(AND(CHARLENE!F16=F16,CHARLENE!G16=G16),"Win","Lose") -> Lose | R16: =IF(AND(VALERIE!F16=F16,VALERIE!G16=G16),"Win","Lose") -> Lose | S16: =IF(AND(KESHAV!F16=F16,KESHAV!G16=G16),"Win","Lose") -> Lose | T16: =IF(AND(MOHNISH!F16=F16,MOHNISH!G16=G16),"Win","Lose") -> Lose | U16: =IF(AND(NICOLAS!F16=F16,NICOLAS!G16=G16),"Win","Lose") -> Lose | V16: =IF(AND(JULIEN!F16=F16,JULIEN!G16=G16),"Win","Lose") -> Lose | W16: =IF(AND(ANDREW!F16=F16,ANDREW!G16=G16),"Win","Lose") -> Lose | X16: =IF(AND(JENNA!F16=F16,JENNA!G16=G16),"Win","Lose") -> Lose | Y16: =IF(AND(JANISH!F16=F16,JANISH!G16=G16),"Win","Lose") -> Lose | Z16: =IF(AND(SANDRASEN!F16=F16,SANDRASEN!G16=G16),"Win","Lose") -> Lose | AA16: =IF(AND(JESSY!F16=F16,JESSY!G16=G16),"Win","Lose") -> Lose | AB16: =IF(AND(PRASHANT!F16=F16,PRASHANT!G16=G16),"Win","Lose") -> Lose | AC16: =IF(AND(GEETIKA!F16=F16,GEETIKA!G16=G16),"Win","Lose") -> Lose | AD16: =IF(AND(JOAKIM!F16=F16,JOAKIM!G16=G16),"Win","Lose") -> Lose | AE16: =IF(AND(OUVARSHI!F16=F16,OUVARSHI!G16=G16),"Win","Lose") -> Lose | AF16: =IF(AND(STEPHAN!F16=F16,STEPHAN!G16=G16),"Win","Lose") -> Lose | AG16: =IF(AND(IRFAAN!F18=F18,IRFAAN!G18=G18),"Win","Lose") -> Lose | AH16: =IF(AND(ERVIN!F18=F18,ERVIN!G18=G18),"Win","Lose") -> Lose | AI16: =IF(AND(NOEMIE!F18=F18,NOEMIE!G18=G18),"Win","Lose") -> Lose | AJ16: =IF(AND(ISFAAQ!F16=F16,ISFAAQ!G16=G16),"Win","Lose") -> Lose | AK16: =IF(AND(AHMAD!F16=F16,AHMAD!G16=G16),"Win","Lose") -> Lose | AL16: =IF(AND(PARIKSHIT!F16=F16,PARIKSHIT!G16=G16),"Win","Lose") -> Lose | AM16: =IF(AND(JAYA!F16=F16,JAYA!G16=G16),"Win","Lose") -> Lose | AN16: =IF(AND(Elodie!F16=F16,Elodie!G16=G16),"Win","Lose") -> Lose | AO16: =IF(AND(RAVINDRA!F16=F16,RAVINDRA!G16=G16),"Win","Lose") -> Lose | AP16: =IF(AND(Jessen!F16=F16,Jessen!G16=G16),"Win","Lose") -> Lose | AQ16: =IF(AND(Annavi!F16=F16,Annavi!G16=G16),"Win","Lose") -> Lose | AR16: =IF(AND(LUDOVIC!F16=F16,LUDOVIC!G16=G16),"Win","Lose") -> Lose | AS16: =IF(AND(Nathalie!F16=F16,Nathalie!G16=G16),"Win","Lose") -> Lose | AT16: =IF(AND(Akshay!F16=F16,Akshay!G16=G16),"Win","Lose") -> Lose | AU16: =IF(AND(Bavish!F16=F16,Bavish!G16=G16),"Win","Lose") -> Lose | AV16: =IF(AND(Itish!F16=F16,Itish!G16=G16),"Win","Lose") -> Lose | AW16: =IF(AND(Oumar!F16=F16,Oumar!G16=G16),"Win","Lose") -> Lose | AX16: =IF(AND(Kesh!F16=F16,Kesh!G16=G16),"Win","Lose") -> Lose | AY16: =IF(AND(ADHISH!F16=F16,ADHISH!G16=G16),"Win","Lose") -> Lose | AZ16: =IF(AND(Vishnee!F16=F16,Vishnee!G16=G16),"Win","Lose") -> Lose | BA16: =IF(AND(Sebastien!F16=F16,Sebastien!G16=G16),"Win","Lose") -> Lose | BB16: =IF(AND(Soneea!F16=F16,Soneea!G16=G16),"Win","Lose") -> Lose | BC16: =IF(AND(Geraldine!F16=F16,Geraldine!G16=G16),"Win","Lose") -> Lose | BD16: =IF(AND(Chaya!F16=F16,Chaya!G16=G16),"Win","Lose") -> Lose | BE16: =IF(AND(Reshmi!F16=F16,Reshmi!G16=G16),"Win","Lose") -> Lose
A17: 12 | B17: Mon | C17: Jun 15, 2026 | D17: 0.083333333 | E17: Sweden | H17: Tunisia | I17: =IF(AND(RYAN!F17=F17,RYAN!G17=G17),"Win","Lose") -> Lose | J17: =IF(AND(JONATHAN!F17=F17,JONATHAN!G17=G17),"Win","Lose") -> Lose | K17: =IF(AND(RAADIN!F17=F17,RAADIN!G17=G17),"Win","Lose") -> Lose | L17: =IF(AND(TANIA!F17=F17,TANIA!G17=G17),"Win","Lose") -> Lose | M17: =IF(AND(JEFF!F17=F17,JEFF!G17=G17),"Win","Lose") -> Lose | N17: =IF(AND(LUW!F17=F17,LUW!G17=G17),"Win","Lose") -> Lose | O17: =IF(AND(ASHRAF!F17=F17,ASHRAF!G17=G17),"Win","Lose") -> Lose | P17: =IF(AND(NAOMI!F17=F17,NAOMI!G17=G17),"Win","Lose") -> Lose | Q17: =IF(AND(CHARLENE!F17=F17,CHARLENE!G17=G17),"Win","Lose") -> Lose | R17: =IF(AND(VALERIE!F17=F17,VALERIE!G17=G17),"Win","Lose") -> Lose | S17: =IF(AND(KESHAV!F17=F17,KESHAV!G17=G17),"Win","Lose") -> Lose | T17: =IF(AND(MOHNISH!F17=F17,MOHNISH!G17=G17),"Win","Lose") -> Lose | U17: =IF(AND(NICOLAS!F17=F17,NICOLAS!G17=G17),"Win","Lose") -> Lose | V17: =IF(AND(JULIEN!F17=F17,JULIEN!G17=G17),"Win","Lose") -> Lose | W17: =IF(AND(ANDREW!F17=F17,ANDREW!G17=G17),"Win","Lose") -> Lose | X17: =IF(AND(JENNA!F17=F17,JENNA!G17=G17),"Win","Lose") -> Lose | Y17: =IF(AND(JANISH!F17=F17,JANISH!G17=G17),"Win","Lose") -> Lose | Z17: =IF(AND(SANDRASEN!F17=F17,SANDRASEN!G17=G17),"Win","Lose") -> Lose | AA17: =IF(AND(JESSY!F17=F17,JESSY!G17=G17),"Win","Lose") -> Lose | AB17: =IF(AND(PRASHANT!F17=F17,PRASHANT!G17=G17),"Win","Lose") -> Lose | AC17: =IF(AND(GEETIKA!F17=F17,GEETIKA!G17=G17),"Win","Lose") -> Lose | AD17: =IF(AND(JOAKIM!F17=F17,JOAKIM!G17=G17),"Win","Lose") -> Lose | AE17: =IF(AND(OUVARSHI!F17=F17,OUVARSHI!G17=G17),"Win","Lose") -> Lose | AF17: =IF(AND(STEPHAN!F17=F17,STEPHAN!G17=G17),"Win","Lose") -> Lose | AG17: =IF(AND(IRFAAN!F19=F19,IRFAAN!G19=G19),"Win","Lose") -> Lose | AH17: =IF(AND(ERVIN!F19=F19,ERVIN!G19=G19),"Win","Lose") -> Lose | AI17: =IF(AND(NOEMIE!F19=F19,NOEMIE!G19=G19),"Win","Lose") -> Lose | AJ17: =IF(AND(ISFAAQ!F17=F17,ISFAAQ!G17=G17),"Win","Lose") -> Lose | AK17: =IF(AND(AHMAD!F17=F17,AHMAD!G17=G17),"Win","Lose") -> Lose | AL17: =IF(AND(PARIKSHIT!F17=F17,PARIKSHIT!G17=G17),"Win","Lose") -> Lose | AM17: =IF(AND(JAYA!F17=F17,JAYA!G17=G17),"Win","Lose") -> Lose | AN17: =IF(AND(Elodie!F17=F17,Elodie!G17=G17),"Win","Lose") -> Lose | AO17: =IF(AND(RAVINDRA!F17=F17,RAVINDRA!G17=G17),"Win","Lose") -> Lose | AP17: =IF(AND(Jessen!F17=F17,Jessen!G17=G17),"Win","Lose") -> Lose | AQ17: =IF(AND(Annavi!F17=F17,Annavi!G17=G17),"Win","Lose") -> Lose | AR17: =IF(AND(LUDOVIC!F17=F17,LUDOVIC!G17=G17),"Win","Lose") -> Lose | AS17: =IF(AND(Nathalie!F17=F17,Nathalie!G17=G17),"Win","Lose") -> Lose | AT17: =IF(AND(Akshay!F17=F17,Akshay!G17=G17),"Win","Lose") -> Lose | AU17: =IF(AND(Bavish!F17=F17,Bavish!G17=G17),"Win","Lose") -> Lose | AV17: =IF(AND(Itish!F17=F17,Itish!G17=G17),"Win","Lose") -> Lose | AW17: =IF(AND(Oumar!F17=F17,Oumar!G17=G17),"Win","Lose") -> Lose | AX17: =IF(AND(Kesh!F17=F17,Kesh!G17=G17),"Win","Lose") -> Lose | AY17: =IF(AND(ADHISH!F17=F17,ADHISH!G17=G17),"Win","Lose") -> Lose | AZ17: =IF(AND(Vishnee!F17=F17,Vishnee!G17=G17),"Win","Lose") -> Lose | BA17: =IF(AND(Sebastien!F17=F17,Sebastien!G17=G17),"Win","Lose") -> Lose | BB17: =IF(AND(Soneea!F17=F17,Soneea!G17=G17),"Win","Lose") -> Lose | BC17: =IF(AND(Geraldine!F17=F17,Geraldine!G17=G17),"Win","Lose") -> Lose | BD17: =IF(AND(Chaya!F17=F17,Chaya!G17=G17),"Win","Lose") -> Lose | BE17: =IF(AND(Reshmi!F17=F17,Reshmi!G17=G17),"Win","Lose") -> Lose
A18: 13 | B18: Mon | C18: Jun 15, 2026 | D18: 0.91666667 | E18: Saudi Arabia | H18: Uruguay | I18: =IF(AND(RYAN!F18=F18,RYAN!G18=G18),"Win","Lose") -> Lose | J18: =IF(AND(JONATHAN!F18=F18,JONATHAN!G18=G18),"Win","Lose") -> Lose | K18: =IF(AND(RAADIN!F18=F18,RAADIN!G18=G18),"Win","Lose") -> Lose | L18: =IF(AND(TANIA!F18=F18,TANIA!G18=G18),"Win","Lose") -> Lose | M18: =IF(AND(JEFF!F18=F18,JEFF!G18=G18),"Win","Lose") -> Lose | N18: =IF(AND(LUW!F18=F18,LUW!G18=G18),"Win","Lose") -> Lose | O18: =IF(AND(ASHRAF!F18=F18,ASHRAF!G18=G18),"Win","Lose") -> Lose | P18: =IF(AND(NAOMI!F18=F18,NAOMI!G18=G18),"Win","Lose") -> Lose | Q18: =IF(AND(CHARLENE!F18=F18,CHARLENE!G18=G18),"Win","Lose") -> Lose | R18: =IF(AND(VALERIE!F18=F18,VALERIE!G18=G18),"Win","Lose") -> Lose | S18: =IF(AND(KESHAV!F18=F18,KESHAV!G18=G18),"Win","Lose") -> Win | T18: =IF(AND(MOHNISH!F18=F18,MOHNISH!G18=G18),"Win","Lose") -> Lose | U18: =IF(AND(NICOLAS!F18=F18,NICOLAS!G18=G18),"Win","Lose") -> Lose | V18: =IF(AND(JULIEN!F18=F18,JULIEN!G18=G18),"Win","Lose") -> Lose | W18: =IF(AND(ANDREW!F18=F18,ANDREW!G18=G18),"Win","Lose") -> Lose | X18: =IF(AND(JENNA!F18=F18,JENNA!G18=G18),"Win","Lose") -> Lose | Y18: =IF(AND(JANISH!F18=F18,JANISH!G18=G18),"Win","Lose") -> Lose | Z18: =IF(AND(SANDRASEN!F18=F18,SANDRASEN!G18=G18),"Win","Lose") -> Lose | AA18: =IF(AND(JESSY!F18=F18,JESSY!G18=G18),"Win","Lose") -> Lose | AB18: =IF(AND(PRASHANT!F18=F18,PRASHANT!G18=G18),"Win","Lose") -> Lose | AC18: =IF(AND(GEETIKA!F18=F18,GEETIKA!G18=G18),"Win","Lose") -> Lose | AD18: =IF(AND(JOAKIM!F18=F18,JOAKIM!G18=G18),"Win","Lose") -> Lose | AE18: =IF(AND(OUVARSHI!F18=F18,OUVARSHI!G18=G18),"Win","Lose") -> Lose | AF18: =IF(AND(STEPHAN!F18=F18,STEPHAN!G18=G18),"Win","Lose") -> Lose | AG18: =IF(AND(IRFAAN!F20=F20,IRFAAN!G20=G20),"Win","Lose") -> Lose | AH18: =IF(AND(ERVIN!F20=F20,ERVIN!G20=G20),"Win","Lose") -> Lose | AI18: =IF(AND(NOEMIE!F20=F20,NOEMIE!G20=G20),"Win","Lose") -> Lose | AJ18: =IF(AND(ISFAAQ!F18=F18,ISFAAQ!G18=G18),"Win","Lose") -> Lose | AK18: =IF(AND(AHMAD!F18=F18,AHMAD!G18=G18),"Win","Lose") -> Lose | AL18: =IF(AND(PARIKSHIT!F18=F18,PARIKSHIT!G18=G18),"Win","Lose") -> Lose | AM18: =IF(AND(JAYA!F18=F18,JAYA!G18=G18),"Win","Lose") -> Lose | AN18: =IF(AND(Elodie!F18=F18,Elodie!G18=G18),"Win","Lose") -> Lose | AO18: =IF(AND(RAVINDRA!F18=F18,RAVINDRA!G18=G18),"Win","Lose") -> Lose | AP18: =IF(AND(Jessen!F18=F18,Jessen!G18=G18),"Win","Lose") -> Lose | AQ18: =IF(AND(Annavi!F18=F18,Annavi!G18=G18),"Win","Lose") -> Lose | AR18: =IF(AND(LUDOVIC!F18=F18,LUDOVIC!G18=G18),"Win","Lose") -> Lose | AS18: =IF(AND(Nathalie!F18=F18,Nathalie!G18=G18),"Win","Lose") -> Lose | AT18: =IF(AND(Akshay!F18=F18,Akshay!G18=G18),"Win","Lose") -> Lose | AU18: =IF(AND(Bavish!F18=F18,Bavish!G18=G18),"Win","Lose") -> Lose | AV18: =IF(AND(Itish!F18=F18,Itish!G18=G18),"Win","Lose") -> Lose | AW18: =IF(AND(Oumar!F18=F18,Oumar!G18=G18),"Win","Lose") -> Lose | AX18: =IF(AND(Kesh!F18=F18,Kesh!G18=G18),"Win","Lose") -> Lose | AY18: =IF(AND(ADHISH!F18=F18,ADHISH!G18=G18),"Win","Lose") -> Lose | AZ18: =IF(AND(Vishnee!F18=F18,Vishnee!G18=G18),"Win","Lose") -> Lose | BA18: =IF(AND(Sebastien!F18=F18,Sebastien!G18=G18),"Win","Lose") -> Lose | BB18: =IF(AND(Soneea!F18=F18,Soneea!G18=G18),"Win","Lose") -> Lose | BC18: =IF(AND(Geraldine!F18=F18,Geraldine!G18=G18),"Win","Lose") -> Lose | BD18: =IF(AND(Chaya!F18=F18,Chaya!G18=G18),"Win","Lose") -> Lose | BE18: =IF(AND(Reshmi!F18=F18,Reshmi!G18=G18),"Win","Lose") -> Lose
A19: 14 | B19: Mon | C19: Jun 15, 2026 | D19: 0.66666667 | E19: Spain | H19: Cape Verde | I19: =IF(AND(RYAN!F19=F19,RYAN!G19=G19),"Win","Lose") -> Lose | J19: =IF(AND(JONATHAN!F19=F19,JONATHAN!G19=G19),"Win","Lose") -> Lose | K19: =IF(AND(RAADIN!F19=F19,RAADIN!G19=G19),"Win","Lose") -> Lose | L19: =IF(AND(TANIA!F19=F19,TANIA!G19=G19),"Win","Lose") -> Lose | M19: =IF(AND(JEFF!F19=F19,JEFF!G19=G19),"Win","Lose") -> Lose | N19: =IF(AND(LUW!F19=F19,LUW!G19=G19),"Win","Lose") -> Lose | O19: =IF(AND(ASHRAF!F19=F19,ASHRAF!G19=G19),"Win","Lose") -> Lose | P19: =IF(AND(NAOMI!F19=F19,NAOMI!G19=G19),"Win","Lose") -> Lose | Q19: =IF(AND(CHARLENE!F19=F19,CHARLENE!G19=G19),"Win","Lose") -> Lose | R19: =IF(AND(VALERIE!F19=F19,VALERIE!G19=G19),"Win","Lose") -> Lose | S19: =IF(AND(KESHAV!F19=F19,KESHAV!G19=G19),"Win","Lose") -> Lose | T19: =IF(AND(MOHNISH!F19=F19,MOHNISH!G19=G19),"Win","Lose") -> Lose | U19: =IF(AND(NICOLAS!F19=F19,NICOLAS!G19=G19),"Win","Lose") -> Lose | V19: =IF(AND(JULIEN!F19=F19,JULIEN!G19=G19),"Win","Lose") -> Lose | W19: =IF(AND(ANDREW!F19=F19,ANDREW!G19=G19),"Win","Lose") -> Lose | X19: =IF(AND(JENNA!F19=F19,JENNA!G19=G19),"Win","Lose") -> Lose | Y19: =IF(AND(JANISH!F19=F19,JANISH!G19=G19),"Win","Lose") -> Lose | Z19: =IF(AND(SANDRASEN!F19=F19,SANDRASEN!G19=G19),"Win","Lose") -> Lose | AA19: =IF(AND(JESSY!F19=F19,JESSY!G19=G19),"Win","Lose") -> Lose | AB19: =IF(AND(PRASHANT!F19=F19,PRASHANT!G19=G19),"Win","Lose") -> Lose | AC19: =IF(AND(GEETIKA!F19=F19,GEETIKA!G19=G19),"Win","Lose") -> Lose | AD19: =IF(AND(JOAKIM!F19=F19,JOAKIM!G19=G19),"Win","Lose") -> Lose | AE19: =IF(AND(OUVARSHI!F19=F19,OUVARSHI!G19=G19),"Win","Lose") -> Lose | AF19: =IF(AND(STEPHAN!F19=F19,STEPHAN!G19=G19),"Win","Lose") -> Lose | AG19: =IF(AND(IRFAAN!F21=F21,IRFAAN!G21=G21),"Win","Lose") -> Lose | AH19: =IF(AND(ERVIN!F21=F21,ERVIN!G21=G21),"Win","Lose") -> Lose | AI19: =IF(AND(NOEMIE!F21=F21,NOEMIE!G21=G21),"Win","Lose") -> Lose | AJ19: =IF(AND(ISFAAQ!F19=F19,ISFAAQ!G19=G19),"Win","Lose") -> Lose | AK19: =IF(AND(AHMAD!F19=F19,AHMAD!G19=G19),"Win","Lose") -> Lose | AL19: =IF(AND(PARIKSHIT!F19=F19,PARIKSHIT!G19=G19),"Win","Lose") -> Lose | AM19: =IF(AND(JAYA!F19=F19,JAYA!G19=G19),"Win","Lose") -> Lose | AN19: =IF(AND(Elodie!F19=F19,Elodie!G19=G19),"Win","Lose") -> Lose | AO19: =IF(AND(RAVINDRA!F19=F19,RAVINDRA!G19=G19),"Win","Lose") -> Lose | AP19: =IF(AND(Jessen!F19=F19,Jessen!G19=G19),"Win","Lose") -> Lose | AQ19: =IF(AND(Annavi!F19=F19,Annavi!G19=G19),"Win","Lose") -> Lose | AR19: =IF(AND(LUDOVIC!F19=F19,LUDOVIC!G19=G19),"Win","Lose") -> Lose | AS19: =IF(AND(Nathalie!F19=F19,Nathalie!G19=G19),"Win","Lose") -> Lose | AT19: =IF(AND(Akshay!F19=F19,Akshay!G19=G19),"Win","Lose") -> Lose | AU19: =IF(AND(Bavish!F19=F19,Bavish!G19=G19),"Win","Lose") -> Lose | AV19: =IF(AND(Itish!F19=F19,Itish!G19=G19),"Win","Lose") -> Lose | AW19: =IF(AND(Oumar!F19=F19,Oumar!G19=G19),"Win","Lose") -> Lose | AX19: =IF(AND(Kesh!F19=F19,Kesh!G19=G19),"Win","Lose") -> Lose | AY19: =IF(AND(ADHISH!F19=F19,ADHISH!G19=G19),"Win","Lose") -> Lose | AZ19: =IF(AND(Vishnee!F19=F19,Vishnee!G19=G19),"Win","Lose") -> Lose | BA19: =IF(AND(Sebastien!F19=F19,Sebastien!G19=G19),"Win","Lose") -> Lose | BB19: =IF(AND(Soneea!F19=F19,Soneea!G19=G19),"Win","Lose") -> Lose | BC19: =IF(AND(Geraldine!F19=F19,Geraldine!G19=G19),"Win","Lose") -> Lose | BD19: =IF(AND(Chaya!F19=F19,Chaya!G19=G19),"Win","Lose") -> Lose | BE19: =IF(AND(Reshmi!F19=F19,Reshmi!G19=G19),"Win","Lose") -> Lose
... A77: 72 | B77: Sat | C77: Jun 27, 2026 | D77: 0.97916667 | E77: DR Congo | H77: Uzbekistan | I77: =IF(AND(RYAN!F77=F77,RYAN!G77=G77),"Win","Lose") -> Lose | J77: =IF(AND(JONATHAN!F77=F77,JONATHAN!G77=G77),"Win","Lose") -> Lose | K77: =IF(AND(RAADIN!F77=F77,RAADIN!G77=G77),"Win","Lose") -> Lose | L77: =IF(AND(TANIA!F77=F77,TANIA!G77=G77),"Win","Lose") -> Lose | M77: =IF(AND(JEFF!F77=F77,JEFF!G77=G77),"Win","Lose") -> Lose | N77: =IF(AND(LUW!F77=F77,LUW!G77=G77),"Win","Lose") -> Win | O77: =IF(AND(ASHRAF!F77=F77,ASHRAF!G77=G77),"Win","Lose") -> Lose | P77: =IF(AND(NAOMI!F77=F77,NAOMI!G77=G77),"Win","Lose") -> Lose | Q77: =IF(AND(CHARLENE!F77=F77,CHARLENE!G77=G77),"Win","Lose") -> Lose | R77: =IF(AND(VALERIE!F77=F77,VALERIE!G77=G77),"Win","Lose") -> Lose | S77: =IF(AND(KESHAV!F77=F77,KESHAV!G77=G77),"Win","Lose") -> Lose | T77: =IF(AND(MOHNISH!F77=F77,MOHNISH!G77=G77),"Win","Lose") -> Lose | U77: =IF(AND(NICOLAS!F77=F77,NICOLAS!G77=G77),"Win","Lose") -> Lose | V77: =IF(AND(JULIEN!F77=F77,JULIEN!G77=G77),"Win","Lose") -> Lose | W77: =IF(AND(ANDREW!F77=F77,ANDREW!G77=G77),"Win","Lose") -> Lose | X77: =IF(AND(JENNA!F77=F77,JENNA!G77=G77),"Win","Lose") -> Lose | Y77: =IF(AND(JANISH!F77=F77,JANISH!G77=G77),"Win","Lose") -> Win | Z77: =IF(AND(SANDRASEN!F77=F77,SANDRASEN!G77=G77),"Win","Lose") -> Lose | AA77: =IF(AND(JESSY!F77=F77,JESSY!G77=G77),"Win","Lose") -> Lose | AB77: =IF(AND(PRASHANT!F77=F77,PRASHANT!G77=G77),"Win","Lose") -> Win | AC77: =IF(AND(GEETIKA!F77=F77,GEETIKA!G77=G77),"Win","Lose") -> Lose | AD77: =IF(AND(JOAKIM!F77=F77,JOAKIM!G77=G77),"Win","Lose") -> Lose | AE77: =IF(AND(OUVARSHI!F77=F77,OUVARSHI!G77=G77),"Win","Lose") -> Lose | AF77: =IF(AND(STEPHAN!F77=F77,STEPHAN!G77=G77),"Win","Lose") -> Lose | AG77: =IF(AND(IRFAAN!F79=F79,IRFAAN!G79=G79),"Win","Lose") -> Win | AH77: =IF(AND(ERVIN!F79=F79,ERVIN!G79=G79),"Win","Lose") -> Win | AI77: =IF(AND(NOEMIE!F79=F79,NOEMIE!G79=G79),"Win","Lose") -> Win | AJ77: =IF(AND(ISFAAQ!F77=F77,ISFAAQ!G77=G77),"Win","Lose") -> Lose | AK77: =IF(AND(AHMAD!F77=F77,AHMAD!G77=G77),"Win","Lose") -> Lose | AL77: =IF(AND(PARIKSHIT!F77=F77,PARIKSHIT!G77=G77),"Win","Lose") -> Lose | AM77: =IF(AND(JAYA!F77=F77,JAYA!G77=G77),"Win","Lose") -> Win | AN77: =IF(AND(Elodie!F77=F77,Elodie!G77=G77),"Win","Lose") -> Lose | AO77: =IF(AND(RAVINDRA!F77=F77,RAVINDRA!G77=G77),"Win","Lose") -> Lose | AP77: =IF(AND(Jessen!F77=F77,Jessen!G77=G77),"Win","Lose") -> Lose | AQ77: =IF(AND(Annavi!F77=F77,Annavi!G77=G77),"Win","Lose") -> Lose | AR77: =IF(AND(LUDOVIC!F77=F77,LUDOVIC!G77=G77),"Win","Lose") -> Lose | AS77: =IF(AND(Nathalie!F77=F77,Nathalie!G77=G77),"Win","Lose") -> Lose | AT77: =IF(AND(Akshay!F77=F77,Akshay!G77=G77),"Win","Lose") -> Lose | AU77: =IF(AND(Bavish!F77=F77,Bavish!G77=G77),"Win","Lose") -> Lose | AV77: =IF(AND(Itish!F77=F77,Itish!G77=G77),"Win","Lose") -> Lose | AW77: =IF(AND(Oumar!F77=F77,Oumar!G77=G77),"Win","Lose") -> Lose | AX77: =IF(AND(Kesh!F77=F77,Kesh!G77=G77),"Win","Lose") -> Lose | AY77: =IF(AND(ADHISH!F77=F77,ADHISH!G77=G77),"Win","Lose") -> Lose | AZ77: =IF(AND(Vishnee!F77=F77,Vishnee!G77=G77),"Win","Lose") -> Lose | BA77: =IF(AND(Sebastien!F77=F77,Sebastien!G77=G77),"Win","Lose") -> Lose | BB77: =IF(AND(Soneea!F77=F77,Soneea!G77=G77),"Win","Lose") -> Lose | BC77: =IF(AND(Geraldine!F77=F77,Geraldine!G77=G77),"Win","Lose") -> Lose | BD77: =IF(AND(Chaya!F77=F77,Chaya!G77=G77),"Win","Lose") -> Lose | BE77: =IF(AND(Reshmi!F77=F77,Reshmi!G77=G77),"Win","Lose") -> Lose
H78: Total of Win | I78: =COUNTIF(I6:I77,"Win") -> 0 | J78: =COUNTIF(J6:J77,"Win") -> 1 | K78: =COUNTIF(K6:K77,"Win") -> 0 | L78: =COUNTIF(L6:L77,"Win") -> 1 | M78: =COUNTIF(M6:M77,"Win") -> 0 | N78: =COUNTIF(N6:N77,"Win") -> 4 | O78: =COUNTIF(O6:O77,"Win") -> 0 | P78: =COUNTIF(P6:P77,"Win") -> 0 | ... BE78: =COUNTIF(BE6:BE77,"Win") -> 1

Sheet RYAN
A1: Deadline: Thu 11 June, 13:00. Check all scores 10 minutes before; Excel will be locked after.
A4: Group Stage
A6: 1 | B6: Thu | C6: Jun 11, 2026 | D6: 0.79166667 | E6: Mexico | F6: 2 | G6: 1 | H6: South Africa
A7: 2 | B7: Fri | C7: Jun 12, 2026 | D7: 0.083333333 | E7: Korea Republic | F7: 1 | G7: 1 | H7: Czech Republic
A8: 3 | B8: Fri | C8: Jun 12, 2026 | D8: 0.79166667 | E8: Canada | F8: 2 | G8: 0 | H8: Bosnia and Herzegovina
A9: 4 | B9: Sat | C9: Jun 13, 2026 | D9: 0.041666667 | E9: United States | F9: 2 | G9: 0 | H9: Paraguay
A10: 5 | B10: Sun | C10: Jun 14, 2026 | D10: 0.041666667 | E10: Haiti | F10: 0 | G10: 3 | H10: Scotland
A11: 6 | B11: Sun | C11: Jun 14, 2026 | D11: 0.16666667 | E11: Australia | F11: 1 | G11: 1 | H11: Turkey
A12: 7 | B12: Sat | C12: Jun 13, 2026 | D12: 0.91666667 | E12: Brazil | F12: 2 | G12: 1 | H12: Morocco
A13: 8 | B13: Sat | C13: Jun 13, 2026 | D13: 0.79166667 | E13: Qatar | F13: 0 | G13: 3 | H13: Switzerland
A14: 9 | B14: Sun | C14: Jun 14, 2026 | D14: 0.95833333 | E14: Ivory Coast | F14: 1 | G14: 1 | H14: Ecuador
A15: 10 | B15: Sun | C15: Jun 14, 2026 | D15: 0.70833333 | E15: Germany | F15: 4 | G15: 0 | H15: Curaçao
A16: 11 | B16: Sun | C16: Jun 14, 2026 | D16: 0.83333333 | E16: Netherlands | F16: 2 | G16: 1 | H16: Japan
A17: 12 | B17: Mon | C17: Jun 15, 2026 | D17: 0.083333333 | E17: Sweden | F17: 2 | G17: 0 | H17: Tunisia
... A77: 72 | B77: Sat | C77: Jun 27, 2026 | D77: 0.97916667 | E77: DR Congo | F77: 2 | G77: 1 | H77: Uzbekistan

Sheet JONATHAN
A1: Deadline: Thu 11 June, 13:00. Check all scores 10 minutes before; Excel will be locked after.
A4: Group Stage
A6: 1 | B6: Thu | C6: Jun 11, 2026 | D6: 0.79166667 | E6: Mexico | F6: 2 | G6: 0 | H6: South Africa
A7: 2 | B7: Fri | C7: Jun 12, 2026 | D7: 0.083333333 | E7: Korea Republic | F7: 1 | G7: 1 | H7: Czech Republic
A8: 3 | B8: Fri | C8: Jun 12, 2026 | D8: 0.79166667 | E8: Canada | F8: 1 | G8: 1 | H8: Bosnia and Herzegovina
A9: 4 | B9: Sat | C9: Jun 13, 2026 | D9: 0.041666667 | E9: United States | F9: 1 | G9: 2 | H9: Paraguay
A10: 5 | B10: Sun | C10: Jun 14, 2026 | D10: 0.041666667 | E10: Haiti | F10: 0 | G10: 2 | H10: Scotland
A11: 6 | B11: Sun | C11: Jun 14, 2026 | D11: 0.16666667 | E11: Australia | F11: 1 | G11: 2 | H11: Turkey
A12: 7 | B12: Sat | C12: Jun 13, 2026 | D12: 0.91666667 | E12: Brazil | F12: 3 | G12: 0 | H12: Morocco
A13: 8 | B13: Sat | C13: Jun 13, 2026 | D13: 0.79166667 | E13: Qatar | F13: 0 | G13: 2 | H13: Switzerland
A14: 9 | B14: Sun | C14: Jun 14, 2026 | D14: 0.95833333 | E14: Ivory Coast | F14: 2 | G14: 1 | H14: Ecuador
A15: 10 | B15: Sun | C15: Jun 14, 2026 | D15: 0.70833333 | E15: Germany | F15: 3 | G15: 0 | H15: Curaçao
A16: 11 | B16: Sun | C16: Jun 14, 2026 | D16: 0.83333333 | E16: Netherlands | F16: 2 | G16: 1 | H16: Japan
A17: 12 | B17: Mon | C17: Jun 15, 2026 | D17: 0.083333333 | E17: Sweden | F17: 3 | G17: 1 | H17: Tunisia
... A77: 72 | B77: Sat | C77: Jun 27, 2026 | D77: 0.97916667 | E77: DR Congo | F77: 1 | G77: 1 | H77: Uzbekistan

Sheet RAADIN
A1: Deadline: Thu 11 June, 13:00. Check all scores 10 minutes before; Excel will be locked after.
A4: Group Stage
A6: 1 | B6: Thu | C6: Jun 11, 2026 | D6: 0.79166667 | E6: Mexico | F6: 2 | G6: 1 | H6: South Africa
A7: 2 | B7: Fri | C7: Jun 12, 2026 | D7: 0.083333333 | E7: Korea Republic | F7: 1 | G7: 1 | H7: Czech Republic
A8: 3 | B8: Fri | C8: Jun 12, 2026 | D8: 0.79166667 | E8: Canada | F8: 2 | G8: 1 | H8: Bosnia and Herzegovina
A9: 4 | B9: Sat | C9: Jun 13, 2026 | D9: 0.041666667 | E9: United States | F9: 1 | G9: 2 | H9: Paraguay
A10: 5 | B10: Sun | C10: Jun 14, 2026 | D10: 0.041666667 | E10: Haiti | F10: 0 | G10: 2 | H10: Scotland
A11: 6 | B11: Sun | C11: Jun 14, 2026 | D11: 0.16666667 | E11: Australia | F11: 1 | G11: 2 | H11: Turkey
A12: 7 | B12: Sat | C12: Jun 13, 2026 | D12: 0.91666667 | E12: Brazil | F12: 2 | G12: 1 | H12: Morocco
A13: 8 | B13: Sat | C13: Jun 13, 2026 | D13: 0.79166667 | E13: Qatar | F13: 0 | G13: 2 | H13: Switzerland
A14: 9 | B14: Sun | C14: Jun 14, 2026 | D14: 0.95833333 | E14: Ivory Coast | F14: 1 | G14: 1 | H14: Ecuador
A15: 10 | B15: Sun | C15: Jun 14, 2026 | D15: 0.70833333 | E15: Germany | F15: 4 | G15: 0 | H15: Curaçao
A16: 11 | B16: Sun | C16: Jun 14, 2026 | D16: 0.83333333 | E16: Netherlands | F16: 2 | G16: 1 | H16: Japan
A17: 12 | B17: Mon | C17: Jun 15, 2026 | D17: 0.083333333 | E17: Sweden | F17: 2 | G17: 0 | H17: Tunisia
... A77: 72 | B77: Sat | C77: Jun 27, 2026 | D77: 0.97916667 | E77: DR Congo | F77: 0 | G77: 2 | H77: Uzbekistan

Sheet PARIKSHIT
A1: Deadline: Thu 11 June, 13:00. Check all scores 10 minutes before; Excel will be locked after.
A4: Group Stage
A6: 1 | B6: Thu | C6: Jun 11, 2026 | D6: 0.79166667 | E6: Mexico | F6: 3 | G6: 1 | H6: South Africa
A7: 2 | B7: Fri | C7: Jun 12, 2026 | D7: 0.083333333 | E7: Korea Republic | F7: 2 | G7: 1 | H7: Czech Republic
A8: 3 | B8: Fri | C8: Jun 12, 2026 | D8: 0.79166667 | E8: Canada | F8: 2 | G8: 0 | H8: Bosnia and Herzegovina
A9: 4 | B9: Sat | C9: Jun 13, 2026 | D9: 0.041666667 | E9: United States | F9: 2 | G9: 0 | H9: Paraguay
A10: 5 | B10: Sun | C10: Jun 14, 2026 | D10: 0.041666667 | E10: Haiti | F10: 0 | G10: 3 | H10: Scotland
A11: 6 | B11: Sun | C11: Jun 14, 2026 | D11: 0.16666667 | E11: Australia | F11: 1 | G11: 2 | H11: Turkey
A12: 7 | B12: Sat | C12: Jun 13, 2026 | D12: 0.91666667 | E12: Brazil | F12: 3 | G12: 1 | H12: Morocco
A13: 8 | B13: Sat | C13: Jun 13, 2026 | D13: 0.79166667 | E13: Qatar | F13: 0 | G13: 3 | H13: Switzerland
A14: 9 | B14: Sun | C14: Jun 14, 2026 | D14: 0.95833333 | E14: Ivory Coast | F14: 1 | G14: 1 | H14: Ecuador
A15: 10 | B15: Sun | C15: Jun 14, 2026 | D15: 0.70833333 | E15: Germany | F15: 4 | G15: 0 | H15: Curaçao
A16: 11 | B16: Sun | C16: Jun 14, 2026 | D16: 0.83333333 | E16: Netherlands | F16: 3 | G16: 1 | H16: Japan
A17: 12 | B17: Mon | C17: Jun 15, 2026 | D17: 0.083333333 | E17: Sweden | F17: 2 | G17: 0 | H17: Tunisia
... A77: 72 | B77: Sat | C77: Jun 27, 2026 | D77: 0.97916667 | E77: DR Congo | F77: 1 | G77: 0 | H77: Uzbekistan

Sheet Annavi
A1: Deadline: Thu 11 June, 13:00. Check all scores 10 minutes before; Excel will be locked after.
A4: Group Stage
A6: 1 | B6: Thu | C6: Jun 11, 2026 | D6: 0.79166667 | E6: Mexico | F6: 2 | G6: 1 | H6: South Africa
A7: 2 | B7: Fri | C7: Jun 12, 2026 | D7: 0.083333333 | E7: Korea Republic | F7: 1 | G7: 1 | H7: Czech Republic
A8: 3 | B8: Fri | C8: Jun 12, 2026 | D8: 0.79166667 | E8: Canada | F8: 1 | G8: 0 | H8: Bosnia and Herzegovina
A9: 4 | B9: Sat | C9: Jun 13, 2026 | D9: 0.041666667 | E9: United States | F9: 2 | G9: 1 | H9: Paraguay
A10: 5 | B10: Sun | C10: Jun 14, 2026 | D10: 0.041666667 | E10: Haiti | F10: 1 | G10: 2 | H10: Scotland
A11: 6 | B11: Sun | C11: Jun 14, 2026 | D11: 0.16666667 | E11: Australia | F11: 1 | G11: 2 | H11: Turkey
A12: 7 | B12: Sat | C12: Jun 13, 2026 | D12: 0.91666667 | E12: Brazil | F12: 2 | G12: 1 | H12: Morocco
A13: 8 | B13: Sat | C13: Jun 13, 2026 | D13: 0.79166667 | E13: Qatar | F13: 0 | G13: 2 | H13: Switzerland
A14: 9 | B14: Sun | C14: Jun 14, 2026 | D14: 0.95833333 | E14: Ivory Coast | F14: 1 | G14: 0 | H14: Ecuador
A15: 10 | B15: Sun | C15: Jun 14, 2026 | D15: 0.70833333 | E15: Germany | F15: 3 | G15: 0 | H15: Curaçao
A16: 11 | B16: Sun | C16: Jun 14, 2026 | D16: 0.83333333 | E16: Netherlands | F16: 2 | G16: 1 | H16: Japan
A17: 12 | B17: Mon | C17: Jun 15, 2026 | D17: 0.083333333 | E17: Sweden | F17: 1 | G17: 1 | H17: Tunisia
... A77: 72 | B77: Sat | C77: Jun 27, 2026 | D77: 0.97916667 | E77: DR Congo | F77: 1 | G77: 1 | H77: Uzbekistan

Sheet Jessen
A1: Deadline: Thu 11 June, 13:00. Check all scores 10 minutes before; Excel will be locked after.
A4: Group Stage
